Workbook

Sheet January 2026
C1: 2026
C2: Week 1 | G2: Week 2 | N2: Week 3 | U2: Week 4 | AB2: Week 5
C3: Jan | D3: Jan | E3: Jan | F3: Jan | G3: Jan | H3: Jan | I3: Jan | J3: Jan | K3: Jan | L3: Jan | M3: Jan | N3: Jan | O3: Jan | P3: Jan | Q3: Jan | R3: Jan | S3: Jan | T3: Jan | U3: Jan | V3: Jan | W3: Jan | X3: Jan | Y3: Jan | Z3: Jan | AA3: Jan | AB3: Jan | AC3: Jan | AD3: Jan | AE3: Jan | AF3: Jan | AG3: Jan | AH3: Absences this month | AJ3: Absence type | AK3: Code | AL3: Deduction
C4: 1 | D4: 2 | E4: 3 | F4: 4 | G4: 5 | H4: 6 | I4: 7 | J4: 8 | K4: 9 | L4: 10 | M4: 11 | N4: 12 | O4: 13 | P4: 14 | Q4: 15 | R4: 16 | S4: 17 | T4: 18 | U4: 19 | V4: 20 | W4: 21 | X4: 22 | Y4: 23 | Z4: 24 | AA4: 25 | AB4: 26 | AC4: 27 | AD4: 28 | AE4: 29 | AF4: 30 | AG4: 31
C5: Thu | D5: Fri | E5: Sat | F5: Sun | G5: Mon | H5: Tue | I5: Wed | J5: Thu | K5: Fri | L5: Sat | M5: Sun | N5: Mon | O5: Tue | P5: Wed | Q5: Thu | R5: Fri | S5: Sat | T5: Sun | U5: Mon | V5: Tue | W5: Wed | X5: Thu | Y5: Fri | Z5: Sat | AA5: Sun | AB5: Mon | AC5: Tue | AD5: Wed | AE5: Thu | AF5: Fri | AG5: Sat
A6: 1 | B6: Patience Tsikudo | C6: V | D6: V | K6: H | AH6: =(COUNTIF(C6:AG6,"H")*1)+(COUNTIF(C6:AG6,"H1")*0.5)+(COUNTIF(C6:AG6,"H2")*0.5)+(COUNTIF(C6:AG6,"Q")*0.25)+(COUNTIF(C6:AG6,"I")*1)+(COUNTIF(C6:AG6,"S")*0)+(COUNTIF(C6:AG6,"M")*1)+(COUNTIF(C6:AG6,"C")*0)+(COUNTIF(C6:AG6,"V")*1)+(COUNTIF(C6:AG6,"A")*1) -> 3 | AJ6: Holiday | AK6: H | AL6: 1
A7: 6 | B7: Emmanuel Tetteh | C7: V | D7: V | K7: H | R7: I | AH7: =(COUNTIF(C7:AG7,"H")*1)+(COUNTIF(C7:AG7,"H1")*0.5)+(COUNTIF(C7:AG7,"H2")*0.5)+(COUNTIF(C7:AG7,"Q")*0.25)+(COUNTIF(C7:AG7,"I")*1)+(COUNTIF(C7:AG7,"S")*0)+(COUNTIF(C7:AG7,"M")*1)+(COUNTIF(C7:AG7,"C")*0)+(COUNTIF(C7:AG7,"V")*1)+(COUNTIF(C7:AG7,"A")*1) -> 4 | AJ7: Half Day (morning) | AK7: H1 | AL7: 0.5
A8: 7 | B8: Solomon Sefah | C8: V | D8: V | K8: H | AH8: =(COUNTIF(C8:AG8,"H")*1)+(COUNTIF(C8:AG8,"H1")*0.5)+(COUNTIF(C8:AG8,"H2")*0.5)+(COUNTIF(C8:AG8,"Q")*0.25)+(COUNTIF(C8:AG8,"I")*1)+(COUNTIF(C8:AG8,"S")*0)+(COUNTIF(C8:AG8,"M")*1)+(COUNTIF(C8:AG8,"C")*0)+(COUNTIF(C8:AG8,"V")*1)+(COUNTIF(C8:AG8,"A")*1) -> 3 | AJ8: Half Day (afternoon) | AK8: H2 | AL8: 0.5
A9: 8 | B9: Maame Lankar De Veer | C9: V | D9: V | I9: H1 | K9: H | N9: S | AH9: =(COUNTIF(C9:AG9,"H")*1)+(COUNTIF(C9:AG9,"H1")*0.5)+(COUNTIF(C9:AG9,"H2")*0.5)+(COUNTIF(C9:AG9,"Q")*0.25)+(COUNTIF(C9:AG9,"I")*1)+(COUNTIF(C9:AG9,"S")*0)+(COUNTIF(C9:AG9,"M")*1)+(COUNTIF(C9:AG9,"C")*0)+(COUNTIF(C9:AG9,"V")*1)+(COUNTIF(C9:AG9,"A")*1) -> 3.5 | AJ9: Quarter day | AK9: Q | AL9: 0.25
A10: 9 | B10: Joel Akwesi Opoku | C10: V | D10: V | K10: H | AH10: =(COUNTIF(C10:AG10,"H")*1)+(COUNTIF(C10:AG10,"H1")*0.5)+(COUNTIF(C10:AG10,"H2")*0.5)+(COUNTIF(C10:AG10,"Q")*0.25)+(COUNTIF(C10:AG10,"I")*1)+(COUNTIF(C10:AG10,"S")*0)+(COUNTIF(C10:AG10,"M")*1)+(COUNTIF(C10:AG10,"C")*0)+(COUNTIF(C10:AG10,"V")*1)+(COUNTIF(C10:AG10,"A")*1) -> 3 | AJ10: Inactive | AK10: I | AL10: 1
A11: 11 | B11: Samuel Napaa | C11: V | D11: V | K11: H | X11: S | AH11: =(COUNTIF(C11:AG11,"H")*1)+(COUNTIF(C11:AG11,"H1")*0.5)+(COUNTIF(C11:AG11,"H2")*0.5)+(COUNTIF(C11:AG11,"Q")*0.25)+(COUNTIF(C11:AG11,"I")*1)+(COUNTIF(C11:AG11,"S")*0)+(COUNTIF(C11:AG11,"M")*1)+(COUNTIF(C11:AG11,"C")*0)+(COUNTIF(C11:AG11,"V")*1)+(COUNTIF(C11:AG11,"A")*1) -> 3 | AJ11: Sickness | AK11: S | AL11: 0
A12: 13 | B12: Cyril Elorm Dzamaklu | C12: V | D12: V | K12: H | AH12: =(COUNTIF(C12:AG12,"H")*1)+(COUNTIF(C12:AG12,"H1")*0.5)+(COUNTIF(C12:AG12,"H2")*0.5)+(COUNTIF(C12:AG12,"Q")*0.25)+(COUNTIF(C12:AG12,"I")*1)+(COUNTIF(C12:AG12,"S")*0)+(COUNTIF(C12:AG12,"M")*1)+(COUNTIF(C12:AG12,"C")*0)+(COUNTIF(C12:AG12,"V")*1)+(COUNTIF(C12:AG12,"A")*1) -> 3 | AJ12: Maternity/Paternity | AK12: M | AL12: 1
A13: 14 | B13: Edwin Sedem Lawuiekpor | C13: V | D13: V | K13: H | AH13: =(COUNTIF(C13:AG13,"H")*1)+(COUNTIF(C13:AG13,"H1")*0.5)+(COUNTIF(C13:AG13,"H2")*0.5)+(COUNTIF(C13:AG13,"Q")*0.25)+(COUNTIF(C13:AG13,"I")*1)+(COUNTIF(C13:AG13,"S")*0)+(COUNTIF(C13:AG13,"M")*1)+(COUNTIF(C13:AG13,"C")*0)+(COUNTIF(C13:AG13,"V")*1)+(COUNTIF(C13:AG13,"A")*1) -> 3 | AJ13: Compassionate | AK13: C | AL13: 0
A14: 15 | B14: Emmanuel Quansah | C14: V | D14: V | K14: H | AH14: =(COUNTIF(C14:AG14,"H")*1)+(COUNTIF(C14:AG14,"H1")*0.5)+(COUNTIF(C14:AG14,"H2")*0.5)+(COUNTIF(C14:AG14,"Q")*0.25)+(COUNTIF(C14:AG14,"I")*1)+(COUNTIF(C14:AG14,"S")*0)+(COUNTIF(C14:AG14,"M")*1)+(COUNTIF(C14:AG14,"C")*0)+(COUNTIF(C14:AG14,"V")*1)+(COUNTIF(C14:AG14,"A")*1) -> 3 | AJ14: Vacation | AK14: V | AL14: 1
A15: 16 | B15: Ben Oni Dankyi Ofosu | C15: V | D15: V | J15: S | K15: H | U15: S | AH15: =(COUNTIF(C15:AG15,"H")*1)+(COUNTIF(C15:AG15,"H1")*0.5)+(COUNTIF(C15:AG15,"H2")*0.5)+(COUNTIF(C15:AG15,"Q")*0.25)+(COUNTIF(C15:AG15,"I")*1)+(COUNTIF(C15:AG15,"S")*0)+(COUNTIF(C15:AG15,"M")*1)+(COUNTIF(C15:AG15,"C")*0)+(COUNTIF(C15:AG15,"V")*1)+(COUNTIF(C15:AG15,"A")*1) -> 3 | AJ15: Absent/No Show | AK15: A | AL15: 1
A16: 17 | B16: Wahab Amoako Domson | C16: V | D16: V | H16: C | J16: V | K16: H | AH16: =(COUNTIF(C16:AG16,"H")*1)+(COUNTIF(C16:AG16,"H1")*0.5)+(COUNTIF(C16:AG16,"H2")*0.5)+(COUNTIF(C16:AG16,"Q")*0.25)+(COUNTIF(C16:AG16,"I")*1)+(COUNTIF(C16:AG16,"S")*0)+(COUNTIF(C16:AG16,"M")*1)+(COUNTIF(C16:AG16,"C")*0)+(COUNTIF(C16:AG16,"V")*1)+(COUNTIF(C16:AG16,"A")*1) -> 4
A17: 18 | B17: Emmanuel Quarshie | C17: V | D17: V | K17: H | AH17: =(COUNTIF(C17:AG17,"H")*1)+(COUNTIF(C17:AG17,"H1")*0.5)+(COUNTIF(C17:AG17,"H2")*0.5)+(COUNTIF(C17:AG17,"Q")*0.25)+(COUNTIF(C17:AG17,"I")*1)+(COUNTIF(C17:AG17,"S")*0)+(COUNTIF(C17:AG17,"M")*1)+(COUNTIF(C17:AG17,"C")*0)+(COUNTIF(C17:AG17,"V")*1)+(COUNTIF(C17:AG17,"A")*1) -> 3
A18: 19 | B18: Ethel Prempeh | C18: V | D18: V | K18: H | O18: ` | U18: V | AH18: =(COUNTIF(C18:AG18,"H")*1)+(COUNTIF(C18:AG18,"H1")*0.5)+(COUNTIF(C18:AG18,"H2")*0.5)+(COUNTIF(C18:AG18,"Q")*0.25)+(COUNTIF(C18:AG18,"I")*1)+(COUNTIF(C18:AG18,"S")*0)+(COUNTIF(C18:AG18,"M")*1)+(COUNTIF(C18:AG18,"C")*0)+(COUNTIF(C18:AG18,"V")*1)+(COUNTIF(C18:AG18,"A")*1) -> 4
A19: 20 | B19: Isaac Appiah | C19: V | D19: V | K19: H | AH19: =(COUNTIF(C19:AG19,"H")*1)+(COUNTIF(C19:AG19,"H1")*0.5)+(COUNTIF(C19:AG19,"H2")*0.5)+(COUNTIF(C19:AG19,"Q")*0.25)+(COUNTIF(C19:AG19,"I")*1)+(COUNTIF(C19:AG19,"S")*0)+(COUNTIF(C19:AG19,"M")*1)+(COUNTIF(C19:AG19,"C")*0)+(COUNTIF(C19:AG19,"V")*1)+(COUNTIF(C19:AG19,"A")*1) -> 3
AH20: =(COUNTIF(C20:AG20,"H")*1)+(COUNTIF(C20:AG20,"H1")*0.5)+(COUNTIF(C20:AG20,"H2")*0.5)+(COUNTIF(C20:AG20,"Q")*0.25)+(COUNTIF(C20:AG20,"I")*1)+(COUNTIF(C20:AG20,"S")*0)+(COUNTIF(C20:AG20,"M")*1)+(COUNTIF(C20:AG20,"C")*0)+(COUNTIF(C20:AG20,"V")*1)+(COUNTIF(C20:AG20,"A")*1) -> 0
B21: 0 | AH21: =(COUNTIF(C21:AG21,"H")*1)+(COUNTIF(C21:AG21,"H1")*0.5)+(COUNTIF(C21:AG21,"H2")*0.5)+(COUNTIF(C21:AG21,"Q")*0.25)+(COUNTIF(C21:AG21,"I")*1)+(COUNTIF(C21:AG21,"S")*0)+(COUNTIF(C21:AG21,"M")*1)+(COUNTIF(C21:AG21,"C")*0)+(COUNTIF(C21:AG21,"V")*1)+(COUNTIF(C21:AG21,"A")*1) -> 0
B22: 0 | AH22: =(COUNTIF(C22:AG22,"H")*1)+(COUNTIF(C22:AG22,"H1")*0.5)+(COUNTIF(C22:AG22,"H2")*0.5)+(COUNTIF(C22:AG22,"Q")*0.25)+(COUNTIF(C22:AG22,"I")*1)+(COUNTIF(C22:AG22,"S")*0)+(COUNTIF(C22:AG22,"M")*1)+(COUNTIF(C22:AG22,"C")*0)+(COUNTIF(C22:AG22,"V")*1)+(COUNTIF(C22:AG22,"A")*1) -> 0
B23: 0 | AH23: =(COUNTIF(C23:AG23,"H")*1)+(COUNTIF(C23:AG23,"H1")*0.5)+(COUNTIF(C23:AG23,"H2")*0.5)+(COUNTIF(C23:AG23,"Q")*0.25)+(COUNTIF(C23:AG23,"I")*1)+(COUNTIF(C23:AG23,"S")*0)+(COUNTIF(C23:AG23,"M")*1)+(COUNTIF(C23:AG23,"C")*0)+(COUNTIF(C23:AG23,"V")*1)+(COUNTIF(C23:AG23,"A")*1) -> 0
B24: 0 | AH24: =(COUNTIF(C24:AG24,"H")*1)+(COUNTIF(C24:AG24,"H1")*0.5)+(COUNTIF(C24:AG24,"H2")*0.5)+(COUNTIF(C24:AG24,"Q")*0.25)+(COUNTIF(C24:AG24,"I")*1)+(COUNTIF(C24:AG24,"S")*0)+(COUNTIF(C24:AG24,"M")*1)+(COUNTIF(C24:AG24,"C")*0)+(COUNTIF(C24:AG24,"V")*1)+(COUNTIF(C24:AG24,"A")*1) -> 0
B25: 0 | AH25: =(COUNTIF(C25:AG25,"H")*1)+(COUNTIF(C25:AG25,"H1")*0.5)+(COUNTIF(C25:AG25,"H2")*0.5)+(COUNTIF(C25:AG25,"Q")*0.25)+(COUNTIF(C25:AG25,"I")*1)+(COUNTIF(C25:AG25,"S")*0)+(COUNTIF(C25:AG25,"M")*1)+(COUNTIF(C25:AG25,"C")*0)+(COUNTIF(C25:AG25,"V")*1)+(COUNTIF(C25:AG25,"A")*1) -> 0
B26: 0 | AH26: =(COUNTIF(C26:AG26,"H")*1)+(COUNTIF(C26:AG26,"H1")*0.5)+(COUNTIF(C26:AG26,"H2")*0.5)+(COUNTIF(C26:AG26,"Q")*0.25)+(COUNTIF(C26:AG26,"I")*1)+(COUNTIF(C26:AG26,"S")*0)+(COUNTIF(C26:AG26,"M")*1)+(COUNTIF(C26:AG26,"C")*0)+(COUNTIF(C26:AG26,"V")*1)+(COUNTIF(C26:AG26,"A")*1) -> 0
B27: 0 | AH27: =(COUNTIF(C27:AG27,"H")*1)+(COUNTIF(C27:AG27,"H1")*0.5)+(COUNTIF(C27:AG27,"H2")*0.5)+(COUNTIF(C27:AG27,"Q")*0.25)+(COUNTIF(C27:AG27,"I")*1)+(COUNTIF(C27:AG27,"S")*0)+(COUNTIF(C27:AG27,"M")*1)+(COUNTIF(C27:AG27,"C")*0)+(COUNTIF(C27:AG27,"V")*1)+(COUNTIF(C27:AG27,"A")*1) -> 0
B28: 0 | AH28: =(COUNTIF(C28:AG28,"H")*1)+(COUNTIF(C28:AG28,"H1")*0.5)+(COUNTIF(C28:AG28,"H2")*0.5)+(COUNTIF(C28:AG28,"Q")*0.25)+(COUNTIF(C28:AG28,"I")*1)+(COUNTIF(C28:AG28,"S")*0)+(COUNTIF(C28:AG28,"M")*1)+(COUNTIF(C28:AG28,"C")*0)+(COUNTIF(C28:AG28,"V")*1)+(COUNTIF(C28:AG28,"A")*1) -> 0
B29: 0 | AH29: =(COUNTIF(C29:AG29,"H")*1)+(COUNTIF(C29:AG29,"H1")*0.5)+(COUNTIF(C29:AG29,"H2")*0.5)+(COUNTIF(C29:AG29,"Q")*0.25)+(COUNTIF(C29:AG29,"I")*1)+(COUNTIF(C29:AG29,"S")*0)+(COUNTIF(C29:AG29,"M")*1)+(COUNTIF(C29:AG29,"C")*0)+(COUNTIF(C29:AG29,"V")*1)+(COUNTIF(C29:AG29,"A")*1) -> 0
B30: 0 | AH30: =(COUNTIF(C30:AG30,"H")*1)+(COUNTIF(C30:AG30,"H1")*0.5)+(COUNTIF(C30:AG30,"H2")*0.5)+(COUNTIF(C30:AG30,"Q")*0.25)+(COUNTIF(C30:AG30,"I")*1)+(COUNTIF(C30:AG30,"S")*0)+(COUNTIF(C30:AG30,"M")*1)+(COUNTIF(C30:AG30,"C")*0)+(COUNTIF(C30:AG30,"V")*1)+(COUNTIF(C30:AG30,"A")*1) -> 0
B31: 0 | AH31: =(COUNTIF(C31:AG31,"H")*1)+(COUNTIF(C31:AG31,"H1")*0.5)+(COUNTIF(C31:AG31,"H2")*0.5)+(COUNTIF(C31:AG31,"Q")*0.25)+(COUNTIF(C31:AG31,"I")*1)+(COUNTIF(C31:AG31,"S")*0)+(COUNTIF(C31:AG31,"M")*1)+(COUNTIF(C31:AG31,"C")*0)+(COUNTIF(C31:AG31,"V")*1)+(COUNTIF(C31:AG31,"A")*1) -> 0
B32: 0 | AH32: =(COUNTIF(C32:AG32,"H")*1)+(COUNTIF(C32:AG32,"H1")*0.5)+(COUNTIF(C32:AG32,"H2")*0.5)+(COUNTIF(C32:AG32,"Q")*0.25)+(COUNTIF(C32:AG32,"I")*1)+(COUNTIF(C32:AG32,"S")*0)+(COUNTIF(C32:AG32,"M")*1)+(COUNTIF(C32:AG32,"C")*0)+(COUNTIF(C32:AG32,"V")*1)+(COUNTIF(C32:AG32,"A")*1) -> 0
... B55: 0 | AH55: =(COUNTIF(C55:AG55,"H")*1)+(COUNTIF(C55:AG55,"H1")*0.5)+(COUNTIF(C55:AG55,"H2")*0.5)+(COUNTIF(C55:AG55,"Q")*0.25)+(COUNTIF(C55:AG55,"I")*1)+(COUNTIF(C55:AG55,"S")*0)+(COUNTIF(C55:AG55,"M")*1)+(COUNTIF(C55:AG55,"C")*0)+(COUNTIF(C55:AG55,"V")*1)+(COUNTIF(C55:AG55,"A")*1) -> 0

Sheet February 2026
C1: 2026
C2: W5 | D2: Week 6 | K2: Week 7 | R2: Week 8 | Y2: Week 9
C3: Feb | D3: Feb | E3: Feb | F3: Feb | G3: Feb | H3: Feb | I3: Feb | J3: Feb | K3: Feb | L3: Feb | M3: Feb | N3: Feb | O3: Feb | P3: Feb | Q3: Feb | R3: Feb | S3: Feb | T3: Feb | U3: Feb | V3: Feb | W3: Feb | X3: Feb | Y3: Feb | Z3: Feb | AA3: Feb | AB3: Feb | AC3: Feb | AD3: Feb | AE3: Absences this month | AG3: Absence type | AH3: Code | AI3: Deduction
C4: 1 | D4: 2 | E4: 3 | F4: 4 | G4: 5 | H4: 6 | I4: 7 | J4: 8 | K4: 9 | L4: 10 | M4: 11 | N4: 12 | O4: 13 | P4: 14 | Q4: 15 | R4: 16 | S4: 17 | T4: 18 | U4: 19 | V4: 20 | W4: 21 | X4: 22 | Y4: 23 | Z4: 24 | AA4: 25 | AB4: 26 | AC4: 27 | AD4: 28
C5: Sun | D5: Mon | E5: Tue | F5: Wed | G5: Thu | H5: Fri | I5: Sat | J5: Sun | K5: Mon | L5: Tue | M5: Wed | N5: Thu | O5: Fri | P5: Sat | Q5: Sun | R5: Mon | S5: Tue | T5: Wed | U5: Thu | V5: Fri | W5: Sat | X5: Sun | Y5: Mon | Z5: Tue | AA5: Wed | AB5: Thu | AC5: Fri | AD5: Sat
B6: ='January 2026'!B6 -> Patience Tsikudo | AE6: =(COUNTIF(C6:AD6,"H")*1)+(COUNTIF(C6:AD6,"H1")*0.5)+(COUNTIF(C6:AD6,"H2")*0.5)+(COUNTIF(C6:AD6,"Q")*0.25)+(COUNTIF(C6:AD6,"I")*1)+(COUNTIF(C6:AD6,"S")*0)+(COUNTIF(C6:AD6,"M")*1)+(COUNTIF(C6:AD6,"C")*0)+(COUNTIF(C6:AD6,"V")*1)+(COUNTIF(C6:AD6,"A")*1) -> 0 | AG6: Holiday | AH6: H | AI6: 1
B7: ='January 2026'!B7 -> Emmanuel Tetteh | F7: S | H7: S | K7: S | T7: S | U7: S | Z7: S | AA7: S | AB7: H2 | AE7: =(COUNTIF(C7:AD7,"H")*1)+(COUNTIF(C7:AD7,"H1")*0.5)+(COUNTIF(C7:AD7,"H2")*0.5)+(COUNTIF(C7:AD7,"Q")*0.25)+(COUNTIF(C7:AD7,"I")*1)+(COUNTIF(C7:AD7,"S")*0)+(COUNTIF(C7:AD7,"M")*1)+(COUNTIF(C7:AD7,"C")*0)+(COUNTIF(C7:AD7,"V")*1)+(COUNTIF(C7:AD7,"A")*1) -> 0.5 | AG7: Half Day (morning) | AH7: H1 | AI7: 0.5
B8: ='January 2026'!B8 -> Solomon Sefah | F8: M | H8: C | V8: V | AE8: =(COUNTIF(C8:AD8,"H")*1)+(COUNTIF(C8:AD8,"H1")*0.5)+(COUNTIF(C8:AD8,"H2")*0.5)+(COUNTIF(C8:AD8,"Q")*0.25)+(COUNTIF(C8:AD8,"I")*1)+(COUNTIF(C8:AD8,"S")*0)+(COUNTIF(C8:AD8,"M")*1)+(COUNTIF(C8:AD8,"C")*0)+(COUNTIF(C8:AD8,"V")*1)+(COUNTIF(C8:AD8,"A")*1) -> 2 | AG8: Half Day (afternoon) | AH8: H2 | AI8: 0.5
B9: ='January 2026'!B9 -> Maame Lankar De Veer | K9: S | AE9: =(COUNTIF(C9:AD9,"H")*1)+(COUNTIF(C9:AD9,"H1")*0.5)+(COUNTIF(C9:AD9,"H2")*0.5)+(COUNTIF(C9:AD9,"Q")*0.25)+(COUNTIF(C9:AD9,"I")*1)+(COUNTIF(C9:AD9,"S")*0)+(COUNTIF(C9:AD9,"M")*1)+(COUNTIF(C9:AD9,"C")*0)+(COUNTIF(C9:AD9,"V")*1)+(COUNTIF(C9:AD9,"A")*1) -> 0 | AG9: Quarter day | AH9: Q | AI9: 0.25
B10: ='January 2026'!B10 -> Joel Akwesi Opoku | AE10: =(COUNTIF(C10:AD10,"H")*1)+(COUNTIF(C10:AD10,"H1")*0.5)+(COUNTIF(C10:AD10,"H2")*0.5)+(COUNTIF(C10:AD10,"Q")*0.25)+(COUNTIF(C10:AD10,"I")*1)+(COUNTIF(C10:AD10,"S")*0)+(COUNTIF(C10:AD10,"M")*1)+(COUNTIF(C10:AD10,"C")*0)+(COUNTIF(C10:AD10,"V")*1)+(COUNTIF(C10:AD10,"A")*1) -> 0 | AG10: Inactive | AH10: I | AI10: 1
B11: ='January 2026'!B11 -> Samuel Napaa | D11: S | K11: H1 | S11: H2 | AE11: =(COUNTIF(C11:AD11,"H")*1)+(COUNTIF(C11:AD11,"H1")*0.5)+(COUNTIF(C11:AD11,"H2")*0.5)+(COUNTIF(C11:AD11,"Q")*0.25)+(COUNTIF(C11:AD11,"I")*1)+(COUNTIF(C11:AD11,"S")*0)+(COUNTIF(C11:AD11,"M")*1)+(COUNTIF(C11:AD11,"C")*0)+(COUNTIF(C11:AD11,"V")*1)+(COUNTIF(C11:AD11,"A")*1) -> 1 | AG11: Sickness | AH11: S | AI11: 0
B12: ='January 2026'!B12 -> Cyril Elorm Dzamaklu | AE12: =(COUNTIF(C12:AD12,"H")*1)+(COUNTIF(C12:AD12,"H1")*0.5)+(COUNTIF(C12:AD12,"H2")*0.5)+(COUNTIF(C12:AD12,"Q")*0.25)+(COUNTIF(C12:AD12,"I")*1)+(COUNTIF(C12:AD12,"S")*0)+(COUNTIF(C12:AD12,"M")*1)+(COUNTIF(C12:AD12,"C")*0)+(COUNTIF(C12:AD12,"V")*1)+(COUNTIF(C12:AD12,"A")*1) -> 0 | AG12: Maternity/Paternity | AH12: M | AI12: 1
B13: ='January 2026'!B13 -> Edwin Sedem Lawuiekpor | AE13: =(COUNTIF(C13:AD13,"H")*1)+(COUNTIF(C13:AD13,"H1")*0.5)+(COUNTIF(C13:AD13,"H2")*0.5)+(COUNTIF(C13:AD13,"Q")*0.25)+(COUNTIF(C13:AD13,"I")*1)+(COUNTIF(C13:AD13,"S")*0)+(COUNTIF(C13:AD13,"M")*1)+(COUNTIF(C13:AD13,"C")*0)+(COUNTIF(C13:AD13,"V")*1)+(COUNTIF(C13:AD13,"A")*1) -> 0 | AG13: Compassionate | AH13: C | AI13: 0
B14: ='January 2026'!B14 -> Emmanuel Quansah | K14: S | L14: S | M14: S | N14: V | AE14: =(COUNTIF(C14:AD14,"H")*1)+(COUNTIF(C14:AD14,"H1")*0.5)+(COUNTIF(C14:AD14,"H2")*0.5)+(COUNTIF(C14:AD14,"Q")*0.25)+(COUNTIF(C14:AD14,"I")*1)+(COUNTIF(C14:AD14,"S")*0)+(COUNTIF(C14:AD14,"M")*1)+(COUNTIF(C14:AD14,"C")*0)+(COUNTIF(C14:AD14,"V")*1)+(COUNTIF(C14:AD14,"A")*1) -> 1 | AG14: Vacation | AH14: V | AI14: 1
B15: ='January 2026'!B15 -> Ben Oni Dankyi Ofosu | AE15: =(COUNTIF(C15:AD15,"H")*1)+(COUNTIF(C15:AD15,"H1")*0.5)+(COUNTIF(C15:AD15,"H2")*0.5)+(COUNTIF(C15:AD15,"Q")*0.25)+(COUNTIF(C15:AD15,"I")*1)+(COUNTIF(C15:AD15,"S")*0)+(COUNTIF(C15:AD15,"M")*1)+(COUNTIF(C15:AD15,"C")*0)+(COUNTIF(C15:AD15,"V")*1)+(COUNTIF(C15:AD15,"A")*1) -> 0 | AG15: Absent/No Show | AH15: A | AI15: 1
B16: ='January 2026'!B16 -> Wahab Amoako Domson | AE16: =(COUNTIF(C16:AD16,"H")*1)+(COUNTIF(C16:AD16,"H1")*0.5)+(COUNTIF(C16:AD16,"H2")*0.5)+(COUNTIF(C16:AD16,"Q")*0.25)+(COUNTIF(C16:AD16,"I")*1)+(COUNTIF(C16:AD16,"S")*0)+(COUNTIF(C16:AD16,"M")*1)+(COUNTIF(C16:AD16,"C")*0)+(COUNTIF(C16:AD16,"V")*1)+(COUNTIF(C16:AD16,"A")*1) -> 0
B17: ='January 2026'!B17 -> Emmanuel Quarshie | G17: C | K17: V | R17: H1 | V17: Q | AE17: =(COUNTIF(C17:AD17,"H")*1)+(COUNTIF(C17:AD17,"H1")*0.5)+(COUNTIF(C17:AD17,"H2")*0.5)+(COUNTIF(C17:AD17,"Q")*0.25)+(COUNTIF(C17:AD17,"I")*1)+(COUNTIF(C17:AD17,"S")*0)+(COUNTIF(C17:AD17,"M")*1)+(COUNTIF(C17:AD17,"C")*0)+(COUNTIF(C17:AD17,"V")*1)+(COUNTIF(C17:AD17,"A")*1) -> 1.75
B18: ='January 2026'!B18 -> Ethel Prempeh | F18: Q | AE18: =(COUNTIF(C18:AD18,"H")*1)+(COUNTIF(C18:AD18,"H1")*0.5)+(COUNTIF(C18:AD18,"H2")*0.5)+(COUNTIF(C18:AD18,"Q")*0.25)+(COUNTIF(C18:AD18,"I")*1)+(COUNTIF(C18:AD18,"S")*0)+(COUNTIF(C18:AD18,"M")*1)+(COUNTIF(C18:AD18,"C")*0)+(COUNTIF(C18:AD18,"V")*1)+(COUNTIF(C18:AD18,"A")*1) -> 0.25
B19: ='January 2026'!B19 -> Isaac Appiah | AE19: =(COUNTIF(C19:AD19,"H")*1)+(COUNTIF(C19:AD19,"H1")*0.5)+(COUNTIF(C19:AD19,"H2")*0.5)+(COUNTIF(C19:AD19,"Q")*0.25)+(COUNTIF(C19:AD19,"I")*1)+(COUNTIF(C19:AD19,"S")*0)+(COUNTIF(C19:AD19,"M")*1)+(COUNTIF(C19:AD19,"C")*0)+(COUNTIF(C19:AD19,"V")*1)+(COUNTIF(C19:AD19,"A")*1) -> 0
B20: ='January 2026'!B20 -> 0 | M20: Q | AE20: =(COUNTIF(C20:AD20,"H")*1)+(COUNTIF(C20:AD20,"H1")*0.5)+(COUNTIF(C20:AD20,"H2")*0.5)+(COUNTIF(C20:AD20,"Q")*0.25)+(COUNTIF(C20:AD20,"I")*1)+(COUNTIF(C20:AD20,"S")*0)+(COUNTIF(C20:AD20,"M")*1)+(COUNTIF(C20:AD20,"C")*0)+(COUNTIF(C20:AD20,"V")*1)+(COUNTIF(C20:AD20,"A")*1) -> 0.25
B21: ='January 2026'!B21 -> 0 | AE21: =(COUNTIF(C21:AD21,"H")*1)+(COUNTIF(C21:AD21,"H1")*0.5)+(COUNTIF(C21:AD21,"H2")*0.5)+(COUNTIF(C21:AD21,"Q")*0.25)+(COUNTIF(C21:AD21,"I")*1)+(COUNTIF(C21:AD21,"S")*0)+(COUNTIF(C21:AD21,"M")*1)+(COUNTIF(C21:AD21,"C")*0)+(COUNTIF(C21:AD21,"V")*1)+(COUNTIF(C21:AD21,"A")*1) -> 0
B22: ='January 2026'!B22 -> 0 | AE22: =(COUNTIF(C22:AD22,"H")*1)+(COUNTIF(C22:AD22,"H1")*0.5)+(COUNTIF(C22:AD22,"H2")*0.5)+(COUNTIF(C22:AD22,"Q")*0.25)+(COUNTIF(C22:AD22,"I")*1)+(COUNTIF(C22:AD22,"S")*0)+(COUNTIF(C22:AD22,"M")*1)+(COUNTIF(C22:AD22,"C")*0)+(COUNTIF(C22:AD22,"V")*1)+(COUNTIF(C22:AD22,"A")*1) -> 0
B23: ='January 2026'!B23 -> 0 | AE23: =(COUNTIF(C23:AD23,"H")*1)+(COUNTIF(C23:AD23,"H1")*0.5)+(COUNTIF(C23:AD23,"H2")*0.5)+(COUNTIF(C23:AD23,"Q")*0.25)+(COUNTIF(C23:AD23,"I")*1)+(COUNTIF(C23:AD23,"S")*0)+(COUNTIF(C23:AD23,"M")*1)+(COUNTIF(C23:AD23,"C")*0)+(COUNTIF(C23:AD23,"V")*1)+(COUNTIF(C23:AD23,"A")*1) -> 0
B24: ='January 2026'!B24 -> 0 | AE24: =(COUNTIF(C24:AD24,"H")*1)+(COUNTIF(C24:AD24,"H1")*0.5)+(COUNTIF(C24:AD24,"H2")*0.5)+(COUNTIF(C24:AD24,"Q")*0.25)+(COUNTIF(C24:AD24,"I")*1)+(COUNTIF(C24:AD24,"S")*0)+(COUNTIF(C24:AD24,"M")*1)+(COUNTIF(C24:AD24,"C")*0)+(COUNTIF(C24:AD24,"V")*1)+(COUNTIF(C24:AD24,"A")*1) -> 0
B25: ='January 2026'!B25 -> 0 | AE25: =(COUNTIF(C25:AD25,"H")*1)+(COUNTIF(C25:AD25,"H1")*0.5)+(COUNTIF(C25:AD25,"H2")*0.5)+(COUNTIF(C25:AD25,"Q")*0.25)+(COUNTIF(C25:AD25,"I")*1)+(COUNTIF(C25:AD25,"S")*0)+(COUNTIF(C25:AD25,"M")*1)+(COUNTIF(C25:AD25,"C")*0)+(COUNTIF(C25:AD25,"V")*1)+(COUNTIF(C25:AD25,"A")*1) -> 0
B26: ='January 2026'!B26 -> 0 | AE26: =(COUNTIF(C26:AD26,"H")*1)+(COUNTIF(C26:AD26,"H1")*0.5)+(COUNTIF(C26:AD26,"H2")*0.5)+(COUNTIF(C26:AD26,"Q")*0.25)+(COUNTIF(C26:AD26,"I")*1)+(COUNTIF(C26:AD26,"S")*0)+(COUNTIF(C26:AD26,"M")*1)+(COUNTIF(C26:AD26,"C")*0)+(COUNTIF(C26:AD26,"V")*1)+(COUNTIF(C26:AD26,"A")*1) -> 0
B27: ='January 2026'!B27 -> 0 | AE27: =(COUNTIF(C27:AD27,"H")*1)+(COUNTIF(C27:AD27,"H1")*0.5)+(COUNTIF(C27:AD27,"H2")*0.5)+(COUNTIF(C27:AD27,"Q")*0.25)+(COUNTIF(C27:AD27,"I")*1)+(COUNTIF(C27:AD27,"S")*0)+(COUNTIF(C27:AD27,"M")*1)+(COUNTIF(C27:AD27,"C")*0)+(COUNTIF(C27:AD27,"V")*1)+(COUNTIF(C27:AD27,"A")*1) -> 0
B28: ='January 2026'!B28 -> 0 | AE28: =(COUNTIF(C28:AD28,"H")*1)+(COUNTIF(C28:AD28,"H1")*0.5)+(COUNTIF(C28:AD28,"H2")*0.5)+(COUNTIF(C28:AD28,"Q")*0.25)+(COUNTIF(C28:AD28,"I")*1)+(COUNTIF(C28:AD28,"S")*0)+(COUNTIF(C28:AD28,"M")*1)+(COUNTIF(C28:AD28,"C")*0)+(COUNTIF(C28:AD28,"V")*1)+(COUNTIF(C28:AD28,"A")*1) -> 0
B29: ='January 2026'!B29 -> 0 | AE29: =(COUNTIF(C29:AD29,"H")*1)+(COUNTIF(C29:AD29,"H1")*0.5)+(COUNTIF(C29:AD29,"H2")*0.5)+(COUNTIF(C29:AD29,"Q")*0.25)+(COUNTIF(C29:AD29,"I")*1)+(COUNTIF(C29:AD29,"S")*0)+(COUNTIF(C29:AD29,"M")*1)+(COUNTIF(C29:AD29,"C")*0)+(COUNTIF(C29:AD29,"V")*1)+(COUNTIF(C29:AD29,"A")*1) -> 0
B30: ='January 2026'!B30 -> 0 | AE30: =(COUNTIF(C30:AD30,"H")*1)+(COUNTIF(C30:AD30,"H1")*0.5)+(COUNTIF(C30:AD30,"H2")*0.5)+(COUNTIF(C30:AD30,"Q")*0.25)+(COUNTIF(C30:AD30,"I")*1)+(COUNTIF(C30:AD30,"S")*0)+(COUNTIF(C30:AD30,"M")*1)+(COUNTIF(C30:AD30,"C")*0)+(COUNTIF(C30:AD30,"V")*1)+(COUNTIF(C30:AD30,"A")*1) -> 0
B31: ='January 2026'!B31 -> 0 | AE31: =(COUNTIF(C31:AD31,"H")*1)+(COUNTIF(C31:AD31,"H1")*0.5)+(COUNTIF(C31:AD31,"H2")*0.5)+(COUNTIF(C31:AD31,"Q")*0.25)+(COUNTIF(C31:AD31,"I")*1)+(COUNTIF(C31:AD31,"S")*0)+(COUNTIF(C31:AD31,"M")*1)+(COUNTIF(C31:AD31,"C")*0)+(COUNTIF(C31:AD31,"V")*1)+(COUNTIF(C31:AD31,"A")*1) -> 0
B32: ='January 2026'!B32 -> 0 | AE32: =(COUNTIF(C32:AD32,"H")*1)+(COUNTIF(C32:AD32,"H1")*0.5)+(COUNTIF(C32:AD32,"H2")*0.5)+(COUNTIF(C32:AD32,"Q")*0.25)+(COUNTIF(C32:AD32,"I")*1)+(COUNTIF(C32:AD32,"S")*0)+(COUNTIF(C32:AD32,"M")*1)+(COUNTIF(C32:AD32,"C")*0)+(COUNTIF(C32:AD32,"V")*1)+(COUNTIF(C32:AD32,"A")*1) -> 0
... B55: ='January 2026'!B55 -> 0 | AE55: =(COUNTIF(C55:AD55,"H")*1)+(COUNTIF(C55:AD55,"H1")*0.5)+(COUNTIF(C55:AD55,"H2")*0.5)+(COUNTIF(C55:AD55,"Q")*0.25)+(COUNTIF(C55:AD55,"I")*1)+(COUNTIF(C55:AD55,"S")*0)+(COUNTIF(C55:AD55,"M")*1)+(COUNTIF(C55:AD55,"C")*0)+(COUNTIF(C55:AD55,"V")*1)+(COUNTIF(C55:AD55,"A")*1) -> 0

Sheet March 2026
C1: 2026
C2: W9 | D2: Week 10 | K2: Week 11 | R2: Week 12 | Y2: Week 13 | AF2: Week 14
C3: Mar | D3: Mar | E3: Mar | F3: Mar | G3: Mar | H3: Mar | I3: Mar | J3: Mar | K3: Mar | L3: Mar | M3: Mar | N3: Mar | O3: Mar | P3: Mar | Q3: Mar | R3: Mar | S3: Mar | T3: Mar | U3: Mar | V3: Mar | W3: Mar | X3: Mar | Y3: Mar | Z3: Mar | AA3: Mar | AB3: Mar | AC3: Mar | AD3: Mar | AE3: Mar | AF3: Mar | AG3: Mar | AH3: Absences this month | AJ3: Absence type | AK3: Code | AL3: Deduction
C4: 1 | D4: 2 | E4: 3 | F4: 4 | G4: 5 | H4: 6 | I4: 7 | J4: 8 | K4: 9 | L4: 10 | M4: 11 | N4: 12 | O4: 13 | P4: 14 | Q4: 15 | R4: 16 | S4: 17 | T4: 18 | U4: 19 | V4: 20 | W4: 21 | X4: 22 | Y4: 23 | Z4: 24 | AA4: 25 | AB4: 26 | AC4: 27 | AD4: 28 | AE4: 29 | AF4: 30 | AG4: 31
C5: Sun | D5: Mon | E5: Tue | F5: Wed | G5: Thu | H5: Fri | I5: Sat | J5: Sun | K5: Mon | L5: Tue | M5: Wed | N5: Thu | O5: Fri | P5: Sat | Q5: Sun | R5: Mon | S5: Tue | T5: Wed | U5: Thu | V5: Fri | W5: Sat | X5: Sun | Y5: Mon | Z5: Tue | AA5: Wed | AB5: Thu | AC5: Fri | AD5: Sat | AE5: Sun | AF5: Mon | AG5: Tue
B6: ='January 2026'!B6 -> Patience Tsikudo | H6: H | V6: H | Y6: H | AH6: =(COUNTIF(C6:AG6,"H")*1)+(COUNTIF(C6:AG6,"H1")*0.5)+(COUNTIF(C6:AG6,"H2")*0.5)+(COUNTIF(C6:AG6,"Q")*0.25)+(COUNTIF(C6:AG6,"I")*1)+(COUNTIF(C6:AG6,"S")*0)+(COUNTIF(C6:AG6,"M")*1)+(COUNTIF(C6:AG6,"C")*0)+(COUNTIF(C6:AG6,"V")*1)+(COUNTIF(C6:AG6,"A")*1) -> 3 | AJ6: Holiday | AK6: H | AL6: 1
B7: ='January 2026'!B7 -> Emmanuel Tetteh | E7: V | H7: H | R7: M | S7: M | T7: M | V7: H | Y7: H | AH7: =(COUNTIF(C7:AG7,"H")*1)+(COUNTIF(C7:AG7,"H1")*0.5)+(COUNTIF(C7:AG7,"H2")*0.5)+(COUNTIF(C7:AG7,"Q")*0.25)+(COUNTIF(C7:AG7,"I")*1)+(COUNTIF(C7:AG7,"S")*0)+(COUNTIF(C7:AG7,"M")*1)+(COUNTIF(C7:AG7,"C")*0)+(COUNTIF(C7:AG7,"V")*1)+(COUNTIF(C7:AG7,"A")*1) -> 6 | AJ7: Half Day (morning) | AK7: H1 | AL7: 0.5
B8: ='January 2026'!B8 -> Solomon Sefah | H8: H | K8: S | L8: S | M8: S | N8: S | O8: S | R8: S | S8: S | T8: S | V8: H | Y8: H | AH8: =(COUNTIF(C8:AG8,"H")*1)+(COUNTIF(C8:AG8,"H1")*0.5)+(COUNTIF(C8:AG8,"H2")*0.5)+(COUNTIF(C8:AG8,"Q")*0.25)+(COUNTIF(C8:AG8,"I")*1)+(COUNTIF(C8:AG8,"S")*0)+(COUNTIF(C8:AG8,"M")*1)+(COUNTIF(C8:AG8,"C")*0)+(COUNTIF(C8:AG8,"V")*1)+(COUNTIF(C8:AG8,"A")*1) -> 3 | AJ8: Half Day (afternoon) | AK8: H2 | AL8: 0.5
B9: ='January 2026'!B9 -> Maame Lankar De Veer | H9: H | K9: V | V9: H | Y9: H | AG9: S | AH9: =(COUNTIF(C9:AG9,"H")*1)+(COUNTIF(C9:AG9,"H1")*0.5)+(COUNTIF(C9:AG9,"H2")*0.5)+(COUNTIF(C9:AG9,"Q")*0.25)+(COUNTIF(C9:AG9,"I")*1)+(COUNTIF(C9:AG9,"S")*0)+(COUNTIF(C9:AG9,"M")*1)+(COUNTIF(C9:AG9,"C")*0)+(COUNTIF(C9:AG9,"V")*1)+(COUNTIF(C9:AG9,"A")*1) -> 4 | AJ9: Quarter day | AK9: Q | AL9: 0.25
B10: ='January 2026'!B10 -> Joel Akwesi Opoku | H10: H | V10: H | Y10: H | AH10: =(COUNTIF(C10:AG10,"H")*1)+(COUNTIF(C10:AG10,"H1")*0.5)+(COUNTIF(C10:AG10,"H2")*0.5)+(COUNTIF(C10:AG10,"Q")*0.25)+(COUNTIF(C10:AG10,"I")*1)+(COUNTIF(C10:AG10,"S")*0)+(COUNTIF(C10:AG10,"M")*1)+(COUNTIF(C10:AG10,"C")*0)+(COUNTIF(C10:AG10,"V")*1)+(COUNTIF(C10:AG10,"A")*1) -> 3 | AJ10: Inactive | AK10: I | AL10: 1
B11: ='January 2026'!B11 -> Samuel Napaa | H11: H | V11: H | Y11: H | AH11: =(COUNTIF(C11:AG11,"H")*1)+(COUNTIF(C11:AG11,"H1")*0.5)+(COUNTIF(C11:AG11,"H2")*0.5)+(COUNTIF(C11:AG11,"Q")*0.25)+(COUNTIF(C11:AG11,"I")*1)+(COUNTIF(C11:AG11,"S")*0)+(COUNTIF(C11:AG11,"M")*1)+(COUNTIF(C11:AG11,"C")*0)+(COUNTIF(C11:AG11,"V")*1)+(COUNTIF(C11:AG11,"A")*1) -> 3 | AJ11: Sickness | AK11: S | AL11: 0
B12: ='January 2026'!B12 -> Cyril Elorm Dzamaklu | H12: H | R12: V | V12: H | Y12: H | AB12: V | AC12: V | AF12: V | AG12: V | AH12: =(COUNTIF(C12:AG12,"H")*1)+(COUNTIF(C12:AG12,"H1")*0.5)+(COUNTIF(C12:AG12,"H2")*0.5)+(COUNTIF(C12:AG12,"Q")*0.25)+(COUNTIF(C12:AG12,"I")*1)+(COUNTIF(C12:AG12,"S")*0)+(COUNTIF(C12:AG12,"M")*1)+(COUNTIF(C12:AG12,"C")*0)+(COUNTIF(C12:AG12,"V")*1)+(COUNTIF(C12:AG12,"A")*1) -> 8 | AJ12: Maternity/Paternity | AK12: M | AL12: 1
B13: ='January 2026'!B13 -> Edwin Sedem Lawuiekpor | H13: H | K13: S | L13: S | M13: S | N13: S | V13: H | Y13: H | AB13: H2 | AH13: =(COUNTIF(C13:AG13,"H")*1)+(COUNTIF(C13:AG13,"H1")*0.5)+(COUNTIF(C13:AG13,"H2")*0.5)+(COUNTIF(C13:AG13,"Q")*0.25)+(COUNTIF(C13:AG13,"I")*1)+(COUNTIF(C13:AG13,"S")*0)+(COUNTIF(C13:AG13,"M")*1)+(COUNTIF(C13:AG13,"C")*0)+(COUNTIF(C13:AG13,"V")*1)+(COUNTIF(C13:AG13,"A")*1) -> 3.5 | AJ13: Compassionate | AK13: C | AL13: 0
B14: ='January 2026'!B14 -> Emmanuel Quansah | H14: H | K14: V | V14: H | Y14: H | AH14: =(COUNTIF(C14:AG14,"H")*1)+(COUNTIF(C14:AG14,"H1")*0.5)+(COUNTIF(C14:AG14,"H2")*0.5)+(COUNTIF(C14:AG14,"Q")*0.25)+(COUNTIF(C14:AG14,"I")*1)+(COUNTIF(C14:AG14,"S")*0)+(COUNTIF(C14:AG14,"M")*1)+(COUNTIF(C14:AG14,"C")*0)+(COUNTIF(C14:AG14,"V")*1)+(COUNTIF(C14:AG14,"A")*1) -> 4 | AJ14: Vacation | AK14: V | AL14: 1
B15: ='January 2026'!B15 -> Ben Oni Dankyi Ofosu | H15: H | V15: H | Y15: H | AH15: =(COUNTIF(C15:AG15,"H")*1)+(COUNTIF(C15:AG15,"H1")*0.5)+(COUNTIF(C15:AG15,"H2")*0.5)+(COUNTIF(C15:AG15,"Q")*0.25)+(COUNTIF(C15:AG15,"I")*1)+(COUNTIF(C15:AG15,"S")*0)+(COUNTIF(C15:AG15,"M")*1)+(COUNTIF(C15:AG15,"C")*0)+(COUNTIF(C15:AG15,"V")*1)+(COUNTIF(C15:AG15,"A")*1) -> 3 | AJ15: Absent/No Show | AK15: A | AL15: 1
B16: ='January 2026'!B16 -> Wahab Amoako Domson | H16: H | V16: H | Y16: H | AH16: =(COUNTIF(C16:AG16,"H")*1)+(COUNTIF(C16:AG16,"H1")*0.5)+(COUNTIF(C16:AG16,"H2")*0.5)+(COUNTIF(C16:AG16,"Q")*0.25)+(COUNTIF(C16:AG16,"I")*1)+(COUNTIF(C16:AG16,"S")*0)+(COUNTIF(C16:AG16,"M")*1)+(COUNTIF(C16:AG16,"C")*0)+(COUNTIF(C16:AG16,"V")*1)+(COUNTIF(C16:AG16,"A")*1) -> 3
B17: ='January 2026'!B17 -> Emmanuel Quarshie | H17: H | V17: H | Y17: H | AH17: =(COUNTIF(C17:AG17,"H")*1)+(COUNTIF(C17:AG17,"H1")*0.5)+(COUNTIF(C17:AG17,"H2")*0.5)+(COUNTIF(C17:AG17,"Q")*0.25)+(COUNTIF(C17:AG17,"I")*1)+(COUNTIF(C17:AG17,"S")*0)+(COUNTIF(C17:AG17,"M")*1)+(COUNTIF(C17:AG17,"C")*0)+(COUNTIF(C17:AG17,"V")*1)+(COUNTIF(C17:AG17,"A")*1) -> 3
B18: ='January 2026'!B18 -> Ethel Prempeh | H18: H | V18: H | Y18: H | AH18: =(COUNTIF(C18:AG18,"H")*1)+(COUNTIF(C18:AG18,"H1")*0.5)+(COUNTIF(C18:AG18,"H2")*0.5)+(COUNTIF(C18:AG18,"Q")*0.25)+(COUNTIF(C18:AG18,"I")*1)+(COUNTIF(C18:AG18,"S")*0)+(COUNTIF(C18:AG18,"M")*1)+(COUNTIF(C18:AG18,"C")*0)+(COUNTIF(C18:AG18,"V")*1)+(COUNTIF(C18:AG18,"A")*1) -> 3
B19: ='January 2026'!B19 -> Isaac Appiah | H19: H | K19: C | L19: C | M19: C | N19: C | O19: C | V19: H | Y19: H | AH19: =(COUNTIF(C19:AG19,"H")*1)+(COUNTIF(C19:AG19,"H1")*0.5)+(COUNTIF(C19:AG19,"H2")*0.5)+(COUNTIF(C19:AG19,"Q")*0.25)+(COUNTIF(C19:AG19,"I")*1)+(COUNTIF(C19:AG19,"S")*0)+(COUNTIF(C19:AG19,"M")*1)+(COUNTIF(C19:AG19,"C")*0)+(COUNTIF(C19:AG19,"V")*1)+(COUNTIF(C19:AG19,"A")*1) -> 3
B20: ='January 2026'!B20 -> 0 | AH20: =(COUNTIF(C20:AG20,"H")*1)+(COUNTIF(C20:AG20,"H1")*0.5)+(COUNTIF(C20:AG20,"H2")*0.5)+(COUNTIF(C20:AG20,"Q")*0.25)+(COUNTIF(C20:AG20,"I")*1)+(COUNTIF(C20:AG20,"S")*0)+(COUNTIF(C20:AG20,"M")*1)+(COUNTIF(C20:AG20,"C")*0)+(COUNTIF(C20:AG20,"V")*1)+(COUNTIF(C20:AG20,"A")*1) -> 0
B21: ='January 2026'!B21 -> 0 | AH21: =(COUNTIF(C21:AG21,"H")*1)+(COUNTIF(C21:AG21,"H1")*0.5)+(COUNTIF(C21:AG21,"H2")*0.5)+(COUNTIF(C21:AG21,"Q")*0.25)+(COUNTIF(C21:AG21,"I")*1)+(COUNTIF(C21:AG21,"S")*0)+(COUNTIF(C21:AG21,"M")*1)+(COUNTIF(C21:AG21,"C")*0)+(COUNTIF(C21:AG21,"V")*1)+(COUNTIF(C21:AG21,"A")*1) -> 0
B22: ='January 2026'!B22 -> 0 | AH22: =(COUNTIF(C22:AG22,"H")*1)+(COUNTIF(C22:AG22,"H1")*0.5)+(COUNTIF(C22:AG22,"H2")*0.5)+(COUNTIF(C22:AG22,"Q")*0.25)+(COUNTIF(C22:AG22,"I")*1)+(COUNTIF(C22:AG22,"S")*0)+(COUNTIF(C22:AG22,"M")*1)+(COUNTIF(C22:AG22,"C")*0)+(COUNTIF(C22:AG22,"V")*1)+(COUNTIF(C22:AG22,"A")*1) -> 0
B23: ='January 2026'!B23 -> 0 | AH23: =(COUNTIF(C23:AG23,"H")*1)+(COUNTIF(C23:AG23,"H1")*0.5)+(COUNTIF(C23:AG23,"H2")*0.5)+(COUNTIF(C23:AG23,"Q")*0.25)+(COUNTIF(C23:AG23,"I")*1)+(COUNTIF(C23:AG23,"S")*0)+(COUNTIF(C23:AG23,"M")*1)+(COUNTIF(C23:AG23,"C")*0)+(COUNTIF(C23:AG23,"V")*1)+(COUNTIF(C23:AG23,"A")*1) -> 0
B24: ='January 2026'!B24 -> 0 | AH24: =(COUNTIF(C24:AG24,"H")*1)+(COUNTIF(C24:AG24,"H1")*0.5)+(COUNTIF(C24:AG24,"H2")*0.5)+(COUNTIF(C24:AG24,"Q")*0.25)+(COUNTIF(C24:AG24,"I")*1)+(COUNTIF(C24:AG24,"S")*0)+(COUNTIF(C24:AG24,"M")*1)+(COUNTIF(C24:AG24,"C")*0)+(COUNTIF(C24:AG24,"V")*1)+(COUNTIF(C24:AG24,"A")*1) -> 0
B25: ='January 2026'!B25 -> 0 | AH25: =(COUNTIF(C25:AG25,"H")*1)+(COUNTIF(C25:AG25,"H1")*0.5)+(COUNTIF(C25:AG25,"H2")*0.5)+(COUNTIF(C25:AG25,"Q")*0.25)+(COUNTIF(C25:AG25,"I")*1)+(COUNTIF(C25:AG25,"S")*0)+(COUNTIF(C25:AG25,"M")*1)+(COUNTIF(C25:AG25,"C")*0)+(COUNTIF(C25:AG25,"V")*1)+(COUNTIF(C25:AG25,"A")*1) -> 0
B26: ='January 2026'!B26 -> 0 | AH26: =(COUNTIF(C26:AG26,"H")*1)+(COUNTIF(C26:AG26,"H1")*0.5)+(COUNTIF(C26:AG26,"H2")*0.5)+(COUNTIF(C26:AG26,"Q")*0.25)+(COUNTIF(C26:AG26,"I")*1)+(COUNTIF(C26:AG26,"S")*0)+(COUNTIF(C26:AG26,"M")*1)+(COUNTIF(C26:AG26,"C")*0)+(COUNTIF(C26:AG26,"V")*1)+(COUNTIF(C26:AG26,"A")*1) -> 0
B27: ='January 2026'!B27 -> 0 | AH27: =(COUNTIF(C27:AG27,"H")*1)+(COUNTIF(C27:AG27,"H1")*0.5)+(COUNTIF(C27:AG27,"H2")*0.5)+(COUNTIF(C27:AG27,"Q")*0.25)+(COUNTIF(C27:AG27,"I")*1)+(COUNTIF(C27:AG27,"S")*0)+(COUNTIF(C27:AG27,"M")*1)+(COUNTIF(C27:AG27,"C")*0)+(COUNTIF(C27:AG27,"V")*1)+(COUNTIF(C27:AG27,"A")*1) -> 0
B28: ='January 2026'!B28 -> 0 | AH28: =(COUNTIF(C28:AG28,"H")*1)+(COUNTIF(C28:AG28,"H1")*0.5)+(COUNTIF(C28:AG28,"H2")*0.5)+(COUNTIF(C28:AG28,"Q")*0.25)+(COUNTIF(C28:AG28,"I")*1)+(COUNTIF(C28:AG28,"S")*0)+(COUNTIF(C28:AG28,"M")*1)+(COUNTIF(C28:AG28,"C")*0)+(COUNTIF(C28:AG28,"V")*1)+(COUNTIF(C28:AG28,"A")*1) -> 0
B29: ='January 2026'!B29 -> 0 | AH29: =(COUNTIF(C29:AG29,"H")*1)+(COUNTIF(C29:AG29,"H1")*0.5)+(COUNTIF(C29:AG29,"H2")*0.5)+(COUNTIF(C29:AG29,"Q")*0.25)+(COUNTIF(C29:AG29,"I")*1)+(COUNTIF(C29:AG29,"S")*0)+(COUNTIF(C29:AG29,"M")*1)+(COUNTIF(C29:AG29,"C")*0)+(COUNTIF(C29:AG29,"V")*1)+(COUNTIF(C29:AG29,"A")*1) -> 0
B30: ='January 2026'!B30 -> 0 | AH30: =(COUNTIF(C30:AG30,"H")*1)+(COUNTIF(C30:AG30,"H1")*0.5)+(COUNTIF(C30:AG30,"H2")*0.5)+(COUNTIF(C30:AG30,"Q")*0.25)+(COUNTIF(C30:AG30,"I")*1)+(COUNTIF(C30:AG30,"S")*0)+(COUNTIF(C30:AG30,"M")*1)+(COUNTIF(C30:AG30,"C")*0)+(COUNTIF(C30:AG30,"V")*1)+(COUNTIF(C30:AG30,"A")*1) -> 0
B31: ='January 2026'!B31 -> 0 | AH31: =(COUNTIF(C31:AG31,"H")*1)+(COUNTIF(C31:AG31,"H1")*0.5)+(COUNTIF(C31:AG31,"H2")*0.5)+(COUNTIF(C31:AG31,"Q")*0.25)+(COUNTIF(C31:AG31,"I")*1)+(COUNTIF(C31:AG31,"S")*0)+(COUNTIF(C31:AG31,"M")*1)+(COUNTIF(C31:AG31,"C")*0)+(COUNTIF(C31:AG31,"V")*1)+(COUNTIF(C31:AG31,"A")*1) -> 0
... B55: ='January 2026'!B55 -> 0 | AH55: =(COUNTIF(C55:AG55,"H")*1)+(COUNTIF(C55:AG55,"H1")*0.5)+(COUNTIF(C55:AG55,"H2")*0.5)+(COUNTIF(C55:AG55,"Q")*0.25)+(COUNTIF(C55:AG55,"I")*1)+(COUNTIF(C55:AG55,"S")*0)+(COUNTIF(C55:AG55,"M")*1)+(COUNTIF(C55:AG55,"C")*0)+(COUNTIF(C55:AG55,"V")*1)+(COUNTIF(C55:AG55,"A")*1) -> 0

Sheet April 2026
C1: 2026
C2: Week 14 | H2: Week 15 | O2: Week 16 | V2: Week 17 | AC2: Week 18
C3: Apr | D3: Apr | E3: Apr | F3: Apr | G3: Apr | H3: Apr | I3: Apr | J3: Apr | K3: Apr | L3: Apr | M3: Apr | N3: Apr | O3: Apr | P3: Apr | Q3: Apr | R3: Apr | S3: Apr | T3: Apr | U3: Apr | V3: Apr | W3: Apr | X3: Apr | Y3: Apr | Z3: Apr | AA3: Apr | AB3: Apr | AC3: Apr | AD3: Apr | AE3: Apr | AF3: Apr | AG3: Absences this month | AI3: Absence type | AJ3: Code | AK3: Deduction
C4: 1 | D4: 2 | E4: 3 | F4: 4 | G4: 5 | H4: 6 | I4: 7 | J4: 8 | K4: 9 | L4: 10 | M4: 11 | N4: 12 | O4: 13 | P4: 14 | Q4: 15 | R4: 16 | S4: 17 | T4: 18 | U4: 19 | V4: 20 | W4: 21 | X4: 22 | Y4: 23 | Z4: 24 | AA4: 25 | AB4: 26 | AC4: 27 | AD4: 28 | AE4: 29 | AF4: 30
C5: Wed | D5: Thu | E5: Fri | F5: Sat | G5: Sun | H5: Mon | I5: Tue | J5: Wed | K5: Thu | L5: Fri | M5: Sat | N5: Sun | O5: Mon | P5: Tue | Q5: Wed | R5: Thu | S5: Fri | T5: Sat | U5: Sun | V5: Mon | W5: Tue | X5: Wed | Y5: Thu | Z5: Fri | AA5: Sat | AB5: Sun | AC5: Mon | AD5: Tue | AE5: Wed | AF5: Thu
B6: ='January 2026'!B6 -> Patience Tsikudo | D6: M | E6: H | H6: H | AF6: S | AG6: =(COUNTIF(C6:AF6,"H")*1)+(COUNTIF(C6:AF6,"H1")*0.5)+(COUNTIF(C6:AF6,"H2")*0.5)+(COUNTIF(C6:AF6,"Q")*0.25)+(COUNTIF(C6:AF6,"I")*1)+(COUNTIF(C6:AF6,"S")*0)+(COUNTIF(C6:AF6,"M")*1)+(COUNTIF(C6:AF6,"C")*0)+(COUNTIF(C6:AF6,"V")*1)+(COUNTIF(C6:AF6,"A")*1) -> 3 | AI6: Holiday | AJ6: H | AK6: 1
B7: ='January 2026'!B7 -> Emmanuel Tetteh | E7: H | H7: H | Q7: V | R7: V | S7: V | V7: V | W7: V | X7: V | Y7: V | Z7: V | AG7: =(COUNTIF(C7:AF7,"H")*1)+(COUNTIF(C7:AF7,"H1")*0.5)+(COUNTIF(C7:AF7,"H2")*0.5)+(COUNTIF(C7:AF7,"Q")*0.25)+(COUNTIF(C7:AF7,"I")*1)+(COUNTIF(C7:AF7,"S")*0)+(COUNTIF(C7:AF7,"M")*1)+(COUNTIF(C7:AF7,"C")*0)+(COUNTIF(C7:AF7,"V")*1)+(COUNTIF(C7:AF7,"A")*1) -> 10 | AI7: Half Day (morning) | AJ7: H1 | AK7: 0.5
B8: ='January 2026'!B8 -> Solomon Sefah | E8: H | H8: H | AG8: =(COUNTIF(C8:AF8,"H")*1)+(COUNTIF(C8:AF8,"H1")*0.5)+(COUNTIF(C8:AF8,"H2")*0.5)+(COUNTIF(C8:AF8,"Q")*0.25)+(COUNTIF(C8:AF8,"I")*1)+(COUNTIF(C8:AF8,"S")*0)+(COUNTIF(C8:AF8,"M")*1)+(COUNTIF(C8:AF8,"C")*0)+(COUNTIF(C8:AF8,"V")*1)+(COUNTIF(C8:AF8,"A")*1) -> 2 | AI8: Half Day (afternoon) | AJ8: H2 | AK8: 0.5
B9: ='January 2026'!B9 -> Maame Lankar De Veer | D9: S | E9: H | H9: H | J9: V | K9: V | L9: V | P9: V | X9: V | AC9: S | AG9: =(COUNTIF(C9:AF9,"H")*1)+(COUNTIF(C9:AF9,"H1")*0.5)+(COUNTIF(C9:AF9,"H2")*0.5)+(COUNTIF(C9:AF9,"Q")*0.25)+(COUNTIF(C9:AF9,"I")*1)+(COUNTIF(C9:AF9,"S")*0)+(COUNTIF(C9:AF9,"M")*1)+(COUNTIF(C9:AF9,"C")*0)+(COUNTIF(C9:AF9,"V")*1)+(COUNTIF(C9:AF9,"A")*1) -> 7 | AI9: Quarter day | AJ9: Q | AK9: 0.25
B10: ='January 2026'!B10 -> Joel Akwesi Opoku | E10: H | H10: H | R10: A | S10: A | AG10: =(COUNTIF(C10:AF10,"H")*1)+(COUNTIF(C10:AF10,"H1")*0.5)+(COUNTIF(C10:AF10,"H2")*0.5)+(COUNTIF(C10:AF10,"Q")*0.25)+(COUNTIF(C10:AF10,"I")*1)+(COUNTIF(C10:AF10,"S")*0)+(COUNTIF(C10:AF10,"M")*1)+(COUNTIF(C10:AF10,"C")*0)+(COUNTIF(C10:AF10,"V")*1)+(COUNTIF(C10:AF10,"A")*1) -> 2 | AI10: Inactive | AJ10: I | AK10: 1
B11: ='January 2026'!B11 -> Samuel Napaa | E11: H | H11: H | AG11: =(COUNTIF(C11:AF11,"H")*1)+(COUNTIF(C11:AF11,"H1")*0.5)+(COUNTIF(C11:AF11,"H2")*0.5)+(COUNTIF(C11:AF11,"Q")*0.25)+(COUNTIF(C11:AF11,"I")*1)+(COUNTIF(C11:AF11,"S")*0)+(COUNTIF(C11:AF11,"M")*1)+(COUNTIF(C11:AF11,"C")*0)+(COUNTIF(C11:AF11,"V")*1)+(COUNTIF(C11:AF11,"A")*1) -> 2 | AI11: Sickness | AJ11: S | AK11: 0
B12: ='January 2026'!B12 -> Cyril Elorm Dzamaklu | E12: H | H12: H | I12: V | AG12: =(COUNTIF(C12:AF12,"H")*1)+(COUNTIF(C12:AF12,"H1")*0.5)+(COUNTIF(C12:AF12,"H2")*0.5)+(COUNTIF(C12:AF12,"Q")*0.25)+(COUNTIF(C12:AF12,"I")*1)+(COUNTIF(C12:AF12,"S")*0)+(COUNTIF(C12:AF12,"M")*1)+(COUNTIF(C12:AF12,"C")*0)+(COUNTIF(C12:AF12,"V")*1)+(COUNTIF(C12:AF12,"A")*1) -> 3 | AI12: Maternity/Paternity | AJ12: M | AK12: 1
B13: ='January 2026'!B13 -> Edwin Sedem Lawuiekpor | E13: H | H13: H | AG13: =(COUNTIF(C13:AF13,"H")*1)+(COUNTIF(C13:AF13,"H1")*0.5)+(COUNTIF(C13:AF13,"H2")*0.5)+(COUNTIF(C13:AF13,"Q")*0.25)+(COUNTIF(C13:AF13,"I")*1)+(COUNTIF(C13:AF13,"S")*0)+(COUNTIF(C13:AF13,"M")*1)+(COUNTIF(C13:AF13,"C")*0)+(COUNTIF(C13:AF13,"V")*1)+(COUNTIF(C13:AF13,"A")*1) -> 2 | AI13: Compassionate | AJ13: C | AK13: 0
B14: ='January 2026'!B14 -> Emmanuel Quansah | E14: H | H14: H | AC14: V | AG14: =(COUNTIF(C14:AF14,"H")*1)+(COUNTIF(C14:AF14,"H1")*0.5)+(COUNTIF(C14:AF14,"H2")*0.5)+(COUNTIF(C14:AF14,"Q")*0.25)+(COUNTIF(C14:AF14,"I")*1)+(COUNTIF(C14:AF14,"S")*0)+(COUNTIF(C14:AF14,"M")*1)+(COUNTIF(C14:AF14,"C")*0)+(COUNTIF(C14:AF14,"V")*1)+(COUNTIF(C14:AF14,"A")*1) -> 3 | AI14: Vacation | AJ14: V | AK14: 1
B15: ='January 2026'!B15 -> Ben Oni Dankyi Ofosu | D15: V | E15: H | H15: H | AG15: =(COUNTIF(C15:AF15,"H")*1)+(COUNTIF(C15:AF15,"H1")*0.5)+(COUNTIF(C15:AF15,"H2")*0.5)+(COUNTIF(C15:AF15,"Q")*0.25)+(COUNTIF(C15:AF15,"I")*1)+(COUNTIF(C15:AF15,"S")*0)+(COUNTIF(C15:AF15,"M")*1)+(COUNTIF(C15:AF15,"C")*0)+(COUNTIF(C15:AF15,"V")*1)+(COUNTIF(C15:AF15,"A")*1) -> 3 | AI15: Absent/No Show | AJ15: A | AK15: 1
B16: ='January 2026'!B16 -> Wahab Amoako Domson | E16: H | H16: H | AF16: V | AG16: =(COUNTIF(C16:AF16,"H")*1)+(COUNTIF(C16:AF16,"H1")*0.5)+(COUNTIF(C16:AF16,"H2")*0.5)+(COUNTIF(C16:AF16,"Q")*0.25)+(COUNTIF(C16:AF16,"I")*1)+(COUNTIF(C16:AF16,"S")*0)+(COUNTIF(C16:AF16,"M")*1)+(COUNTIF(C16:AF16,"C")*0)+(COUNTIF(C16:AF16,"V")*1)+(COUNTIF(C16:AF16,"A")*1) -> 3
B17: ='January 2026'!B17 -> Emmanuel Quarshie | E17: H | H17: H | O17: S | AE17: S | AG17: =(COUNTIF(C17:AF17,"H")*1)+(COUNTIF(C17:AF17,"H1")*0.5)+(COUNTIF(C17:AF17,"H2")*0.5)+(COUNTIF(C17:AF17,"Q")*0.25)+(COUNTIF(C17:AF17,"I")*1)+(COUNTIF(C17:AF17,"S")*0)+(COUNTIF(C17:AF17,"M")*1)+(COUNTIF(C17:AF17,"C")*0)+(COUNTIF(C17:AF17,"V")*1)+(COUNTIF(C17:AF17,"A")*1) -> 2
B18: ='January 2026'!B18 -> Ethel Prempeh | E18: H | H18: H | AG18: =(COUNTIF(C18:AF18,"H")*1)+(COUNTIF(C18:AF18,"H1")*0.5)+(COUNTIF(C18:AF18,"H2")*0.5)+(COUNTIF(C18:AF18,"Q")*0.25)+(COUNTIF(C18:AF18,"I")*1)+(COUNTIF(C18:AF18,"S")*0)+(COUNTIF(C18:AF18,"M")*1)+(COUNTIF(C18:AF18,"C")*0)+(COUNTIF(C18:AF18,"V")*1)+(COUNTIF(C18:AF18,"A")*1) -> 2
B19: ='January 2026'!B19 -> Isaac Appiah | E19: H | H19: H | AG19: =(COUNTIF(C19:AF19,"H")*1)+(COUNTIF(C19:AF19,"H1")*0.5)+(COUNTIF(C19:AF19,"H2")*0.5)+(COUNTIF(C19:AF19,"Q")*0.25)+(COUNTIF(C19:AF19,"I")*1)+(COUNTIF(C19:AF19,"S")*0)+(COUNTIF(C19:AF19,"M")*1)+(COUNTIF(C19:AF19,"C")*0)+(COUNTIF(C19:AF19,"V")*1)+(COUNTIF(C19:AF19,"A")*1) -> 2
B20: ='January 2026'!B20 -> 0 | AG20: =(COUNTIF(C20:AF20,"H")*1)+(COUNTIF(C20:AF20,"H1")*0.5)+(COUNTIF(C20:AF20,"H2")*0.5)+(COUNTIF(C20:AF20,"Q")*0.25)+(COUNTIF(C20:AF20,"I")*1)+(COUNTIF(C20:AF20,"S")*0)+(COUNTIF(C20:AF20,"M")*1)+(COUNTIF(C20:AF20,"C")*0)+(COUNTIF(C20:AF20,"V")*1)+(COUNTIF(C20:AF20,"A")*1) -> 0
B21: ='January 2026'!B21 -> 0 | AG21: =(COUNTIF(C21:AF21,"H")*1)+(COUNTIF(C21:AF21,"H1")*0.5)+(COUNTIF(C21:AF21,"H2")*0.5)+(COUNTIF(C21:AF21,"Q")*0.25)+(COUNTIF(C21:AF21,"I")*1)+(COUNTIF(C21:AF21,"S")*0)+(COUNTIF(C21:AF21,"M")*1)+(COUNTIF(C21:AF21,"C")*0)+(COUNTIF(C21:AF21,"V")*1)+(COUNTIF(C21:AF21,"A")*1) -> 0
B22: ='January 2026'!B22 -> 0 | AG22: =(COUNTIF(C22:AF22,"H")*1)+(COUNTIF(C22:AF22,"H1")*0.5)+(COUNTIF(C22:AF22,"H2")*0.5)+(COUNTIF(C22:AF22,"Q")*0.25)+(COUNTIF(C22:AF22,"I")*1)+(COUNTIF(C22:AF22,"S")*0)+(COUNTIF(C22:AF22,"M")*1)+(COUNTIF(C22:AF22,"C")*0)+(COUNTIF(C22:AF22,"V")*1)+(COUNTIF(C22:AF22,"A")*1) -> 0
B23: ='January 2026'!B23 -> 0 | AG23: =(COUNTIF(C23:AF23,"H")*1)+(COUNTIF(C23:AF23,"H1")*0.5)+(COUNTIF(C23:AF23,"H2")*0.5)+(COUNTIF(C23:AF23,"Q")*0.25)+(COUNTIF(C23:AF23,"I")*1)+(COUNTIF(C23:AF23,"S")*0)+(COUNTIF(C23:AF23,"M")*1)+(COUNTIF(C23:AF23,"C")*0)+(COUNTIF(C23:AF23,"V")*1)+(COUNTIF(C23:AF23,"A")*1) -> 0
B24: ='January 2026'!B24 -> 0 | AG24: =(COUNTIF(C24:AF24,"H")*1)+(COUNTIF(C24:AF24,"H1")*0.5)+(COUNTIF(C24:AF24,"H2")*0.5)+(COUNTIF(C24:AF24,"Q")*0.25)+(COUNTIF(C24:AF24,"I")*1)+(COUNTIF(C24:AF24,"S")*0)+(COUNTIF(C24:AF24,"M")*1)+(COUNTIF(C24:AF24,"C")*0)+(COUNTIF(C24:AF24,"V")*1)+(COUNTIF(C24:AF24,"A")*1) -> 0
B25: ='January 2026'!B25 -> 0 | AG25: =(COUNTIF(C25:AF25,"H")*1)+(COUNTIF(C25:AF25,"H1")*0.5)+(COUNTIF(C25:AF25,"H2")*0.5)+(COUNTIF(C25:AF25,"Q")*0.25)+(COUNTIF(C25:AF25,"I")*1)+(COUNTIF(C25:AF25,"S")*0)+(COUNTIF(C25:AF25,"M")*1)+(COUNTIF(C25:AF25,"C")*0)+(COUNTIF(C25:AF25,"V")*1)+(COUNTIF(C25:AF25,"A")*1) -> 0
B26: ='January 2026'!B26 -> 0 | AG26: =(COUNTIF(C26:AF26,"H")*1)+(COUNTIF(C26:AF26,"H1")*0.5)+(COUNTIF(C26:AF26,"H2")*0.5)+(COUNTIF(C26:AF26,"Q")*0.25)+(COUNTIF(C26:AF26,"I")*1)+(COUNTIF(C26:AF26,"S")*0)+(COUNTIF(C26:AF26,"M")*1)+(COUNTIF(C26:AF26,"C")*0)+(COUNTIF(C26:AF26,"V")*1)+(COUNTIF(C26:AF26,"A")*1) -> 0
B27: ='January 2026'!B27 -> 0 | AG27: =(COUNTIF(C27:AF27,"H")*1)+(COUNTIF(C27:AF27,"H1")*0.5)+(COUNTIF(C27:AF27,"H2")*0.5)+(COUNTIF(C27:AF27,"Q")*0.25)+(COUNTIF(C27:AF27,"I")*1)+(COUNTIF(C27:AF27,"S")*0)+(COUNTIF(C27:AF27,"M")*1)+(COUNTIF(C27:AF27,"C")*0)+(COUNTIF(C27:AF27,"V")*1)+(COUNTIF(C27:AF27,"A")*1) -> 0
B28: ='January 2026'!B28 -> 0 | AG28: =(COUNTIF(C28:AF28,"H")*1)+(COUNTIF(C28:AF28,"H1")*0.5)+(COUNTIF(C28:AF28,"H2")*0.5)+(COUNTIF(C28:AF28,"Q")*0.25)+(COUNTIF(C28:AF28,"I")*1)+(COUNTIF(C28:AF28,"S")*0)+(COUNTIF(C28:AF28,"M")*1)+(COUNTIF(C28:AF28,"C")*0)+(COUNTIF(C28:AF28,"V")*1)+(COUNTIF(C28:AF28,"A")*1) -> 0
B29: ='January 2026'!B29 -> 0 | AG29: =(COUNTIF(C29:AF29,"H")*1)+(COUNTIF(C29:AF29,"H1")*0.5)+(COUNTIF(C29:AF29,"H2")*0.5)+(COUNTIF(C29:AF29,"Q")*0.25)+(COUNTIF(C29:AF29,"I")*1)+(COUNTIF(C29:AF29,"S")*0)+(COUNTIF(C29:AF29,"M")*1)+(COUNTIF(C29:AF29,"C")*0)+(COUNTIF(C29:AF29,"V")*1)+(COUNTIF(C29:AF29,"A")*1) -> 0
B30: ='January 2026'!B30 -> 0 | AG30: =(COUNTIF(C30:AF30,"H")*1)+(COUNTIF(C30:AF30,"H1")*0.5)+(COUNTIF(C30:AF30,"H2")*0.5)+(COUNTIF(C30:AF30,"Q")*0.25)+(COUNTIF(C30:AF30,"I")*1)+(COUNTIF(C30:AF30,"S")*0)+(COUNTIF(C30:AF30,"M")*1)+(COUNTIF(C30:AF30,"C")*0)+(COUNTIF(C30:AF30,"V")*1)+(COUNTIF(C30:AF30,"A")*1) -> 0
B31: ='January 2026'!B31 -> 0 | AG31: =(COUNTIF(C31:AF31,"H")*1)+(COUNTIF(C31:AF31,"H1")*0.5)+(COUNTIF(C31:AF31,"H2")*0.5)+(COUNTIF(C31:AF31,"Q")*0.25)+(COUNTIF(C31:AF31,"I")*1)+(COUNTIF(C31:AF31,"S")*0)+(COUNTIF(C31:AF31,"M")*1)+(COUNTIF(C31:AF31,"C")*0)+(COUNTIF(C31:AF31,"V")*1)+(COUNTIF(C31:AF31,"A")*1) -> 0
... B55: ='January 2026'!B55 -> 0 | AG55: =(COUNTIF(C55:AF55,"H")*1)+(COUNTIF(C55:AF55,"H1")*0.5)+(COUNTIF(C55:AF55,"H2")*0.5)+(COUNTIF(C55:AF55,"Q")*0.25)+(COUNTIF(C55:AF55,"I")*1)+(COUNTIF(C55:AF55,"S")*0)+(COUNTIF(C55:AF55,"M")*1)+(COUNTIF(C55:AF55,"C")*0)+(COUNTIF(C55:AF55,"V")*1)+(COUNTIF(C55:AF55,"A")*1) -> 0

Sheet May 2026
C1: 2026
C2: Week 18 | F2: Week 19 | M2: Week 20 | T2: Week 21 | AA2: Week 22
C3: May | D3: May | E3: May | F3: May | G3: May | H3: May | I3: May | J3: May | K3: May | L3: May | M3: May | N3: May | O3: May | P3: May | Q3: May | R3: May | S3: May | T3: May | U3: May | V3: May | W3: May | X3: May | Y3: May | Z3: May | AA3: May | AB3: May | AC3: May | AD3: May | AE3: May | AF3: May | AG3: May | AH3: Absences this month | AJ3: Absence type | AK3: Code | AL3: Deduction
C4: 1 | D4: 2 | E4: 3 | F4: 4 | G4: 5 | H4: 6 | I4: 7 | J4: 8 | K4: 9 | L4: 10 | M4: 11 | N4: 12 | O4: 13 | P4: 14 | Q4: 15 | R4: 16 | S4: 17 | T4: 18 | U4: 19 | V4: 20 | W4: 21 | X4: 22 | Y4: 23 | Z4: 24 | AA4: 25 | AB4: 26 | AC4: 27 | AD4: 28 | AE4: 29 | AF4: 30 | AG4: 31
C5: Fri | D5: Sat | E5: Sun | F5: Mon | G5: Tue | H5: Wed | I5: Thu | J5: Fri | K5: Sat | L5: Sun | M5: Mon | N5: Tue | O5: Wed | P5: Thu | Q5: Fri | R5: Sat | S5: Sun | T5: Mon | U5: Tue | V5: Wed | W5: Thu | X5: Fri | Y5: Sat | Z5: Sun | AA5: Mon | AB5: Tue | AC5: Wed | AD5: Thu | AE5: Fri | AF5: Sat | AG5: Sun
B6: ='January 2026'!B6 -> Patience Tsikudo | C6: H | F6: M | G6: M | H6: M | I6: M | J6: M | AC6: H | AH6: =(COUNTIF(C6:AG6,"H")*1)+(COUNTIF(C6:AG6,"H1")*0.5)+(COUNTIF(C6:AG6,"H2")*0.5)+(COUNTIF(C6:AG6,"Q")*0.25)+(COUNTIF(C6:AG6,"I")*1)+(COUNTIF(C6:AG6,"S")*0)+(COUNTIF(C6:AG6,"M")*1)+(COUNTIF(C6:AG6,"C")*0)+(COUNTIF(C6:AG6,"V")*1)+(COUNTIF(C6:AG6,"A")*1) -> 4 | AJ6: Holiday | AK6: H | AL6: 1
B7: ='January 2026'!B7 -> Emmanuel Tetteh | C7: H | AC7: H | AE7: V | AH7: =(COUNTIF(C7:AG7,"H")*1)+(COUNTIF(C7:AG7,"H1")*0.5)+(COUNTIF(C7:AG7,"H2")*0.5)+(COUNTIF(C7:AG7,"Q")*0.25)+(COUNTIF(C7:AG7,"I")*1)+(COUNTIF(C7:AG7,"S")*0)+(COUNTIF(C7:AG7,"M")*1)+(COUNTIF(C7:AG7,"C")*0)+(COUNTIF(C7:AG7,"V")*1)+(COUNTIF(C7:AG7,"A")*1) -> 3 | AJ7: Half Day (morning) | AK7: H1 | AL7: 0.5
B8: ='January 2026'!B8 -> Solomon Sefah | C8: H | AC8: H | AH8: =(COUNTIF(C8:AG8,"H")*1)+(COUNTIF(C8:AG8,"H1")*0.5)+(COUNTIF(C8:AG8,"H2")*0.5)+(COUNTIF(C8:AG8,"Q")*0.25)+(COUNTIF(C8:AG8,"I")*1)+(COUNTIF(C8:AG8,"S")*0)+(COUNTIF(C8:AG8,"M")*1)+(COUNTIF(C8:AG8,"C")*0)+(COUNTIF(C8:AG8,"V")*1)+(COUNTIF(C8:AG8,"A")*1) -> 2 | AJ8: Half Day (afternoon) | AK8: H2 | AL8: 0.5
B9: ='January 2026'!B9 -> Maame Lankar De Veer | C9: H | I9: V | AB9: C | AC9: H | AH9: =(COUNTIF(C9:AG9,"H")*1)+(COUNTIF(C9:AG9,"H1")*0.5)+(COUNTIF(C9:AG9,"H2")*0.5)+(COUNTIF(C9:AG9,"Q")*0.25)+(COUNTIF(C9:AG9,"I")*1)+(COUNTIF(C9:AG9,"S")*0)+(COUNTIF(C9:AG9,"M")*1)+(COUNTIF(C9:AG9,"C")*0)+(COUNTIF(C9:AG9,"V")*1)+(COUNTIF(C9:AG9,"A")*1) -> 3 | AJ9: Quarter day | AK9: Q | AL9: 0.25
B10: ='January 2026'!B10 -> Joel Akwesi Opoku | C10: H | H10: S | AC10: H | AH10: =(COUNTIF(C10:AG10,"H")*1)+(COUNTIF(C10:AG10,"H1")*0.5)+(COUNTIF(C10:AG10,"H2")*0.5)+(COUNTIF(C10:AG10,"Q")*0.25)+(COUNTIF(C10:AG10,"I")*1)+(COUNTIF(C10:AG10,"S")*0)+(COUNTIF(C10:AG10,"M")*1)+(COUNTIF(C10:AG10,"C")*0)+(COUNTIF(C10:AG10,"V")*1)+(COUNTIF(C10:AG10,"A")*1) -> 2 | AJ10: Inactive | AK10: I | AL10: 1
B11: ='January 2026'!B11 -> Samuel Napaa | C11: H | F11: S | G11: S | AC11: H | AH11: =(COUNTIF(C11:AG11,"H")*1)+(COUNTIF(C11:AG11,"H1")*0.5)+(COUNTIF(C11:AG11,"H2")*0.5)+(COUNTIF(C11:AG11,"Q")*0.25)+(COUNTIF(C11:AG11,"I")*1)+(COUNTIF(C11:AG11,"S")*0)+(COUNTIF(C11:AG11,"M")*1)+(COUNTIF(C11:AG11,"C")*0)+(COUNTIF(C11:AG11,"V")*1)+(COUNTIF(C11:AG11,"A")*1) -> 2 | AJ11: Sickness | AK11: S | AL11: 0
B12: ='January 2026'!B12 -> Cyril Elorm Dzamaklu | C12: H | AB12: C | AC12: H | AH12: =(COUNTIF(C12:AG12,"H")*1)+(COUNTIF(C12:AG12,"H1")*0.5)+(COUNTIF(C12:AG12,"H2")*0.5)+(COUNTIF(C12:AG12,"Q")*0.25)+(COUNTIF(C12:AG12,"I")*1)+(COUNTIF(C12:AG12,"S")*0)+(COUNTIF(C12:AG12,"M")*1)+(COUNTIF(C12:AG12,"C")*0)+(COUNTIF(C12:AG12,"V")*1)+(COUNTIF(C12:AG12,"A")*1) -> 2 | AJ12: Maternity/Paternity | AK12: M | AL12: 1
B13: ='January 2026'!B13 -> Edwin Sedem Lawuiekpor | C13: H | W13: V | AC13: H | AH13: =(COUNTIF(C13:AG13,"H")*1)+(COUNTIF(C13:AG13,"H1")*0.5)+(COUNTIF(C13:AG13,"H2")*0.5)+(COUNTIF(C13:AG13,"Q")*0.25)+(COUNTIF(C13:AG13,"I")*1)+(COUNTIF(C13:AG13,"S")*0)+(COUNTIF(C13:AG13,"M")*1)+(COUNTIF(C13:AG13,"C")*0)+(COUNTIF(C13:AG13,"V")*1)+(COUNTIF(C13:AG13,"A")*1) -> 3 | AJ13: Compassionate Leave | AK13: C | AL13: 0
B14: ='January 2026'!B14 -> Emmanuel Quansah | C14: H | AC14: H | AH14: =(COUNTIF(C14:AG14,"H")*1)+(COUNTIF(C14:AG14,"H1")*0.5)+(COUNTIF(C14:AG14,"H2")*0.5)+(COUNTIF(C14:AG14,"Q")*0.25)+(COUNTIF(C14:AG14,"I")*1)+(COUNTIF(C14:AG14,"S")*0)+(COUNTIF(C14:AG14,"M")*1)+(COUNTIF(C14:AG14,"C")*0)+(COUNTIF(C14:AG14,"V")*1)+(COUNTIF(C14:AG14,"A")*1) -> 2 | AJ14: Vacation | AK14: V | AL14: 1
B15: ='January 2026'!B15 -> Ben Oni Dankyi Ofosu | C15: H | J15: V | M15: V | AC15: H | AH15: =(COUNTIF(C15:AG15,"H")*1)+(COUNTIF(C15:AG15,"H1")*0.5)+(COUNTIF(C15:AG15,"H2")*0.5)+(COUNTIF(C15:AG15,"Q")*0.25)+(COUNTIF(C15:AG15,"I")*1)+(COUNTIF(C15:AG15,"S")*0)+(COUNTIF(C15:AG15,"M")*1)+(COUNTIF(C15:AG15,"C")*0)+(COUNTIF(C15:AG15,"V")*1)+(COUNTIF(C15:AG15,"A")*1) -> 4 | AJ15: Absent/No Show | AK15: A | AL15: 1
B16: ='January 2026'!B16 -> Wahab Amoako Domson | C16: H | H16: S | I16: S | J16: S | AC16: H | AH16: =(COUNTIF(C16:AG16,"H")*1)+(COUNTIF(C16:AG16,"H1")*0.5)+(COUNTIF(C16:AG16,"H2")*0.5)+(COUNTIF(C16:AG16,"Q")*0.25)+(COUNTIF(C16:AG16,"I")*1)+(COUNTIF(C16:AG16,"S")*0)+(COUNTIF(C16:AG16,"M")*1)+(COUNTIF(C16:AG16,"C")*0)+(COUNTIF(C16:AG16,"V")*1)+(COUNTIF(C16:AG16,"A")*1) -> 2
B17: ='January 2026'!B17 -> Emmanuel Quarshie | C17: H | AC17: H | AH17: =(COUNTIF(C17:AG17,"H")*1)+(COUNTIF(C17:AG17,"H1")*0.5)+(COUNTIF(C17:AG17,"H2")*0.5)+(COUNTIF(C17:AG17,"Q")*0.25)+(COUNTIF(C17:AG17,"I")*1)+(COUNTIF(C17:AG17,"S")*0)+(COUNTIF(C17:AG17,"M")*1)+(COUNTIF(C17:AG17,"C")*0)+(COUNTIF(C17:AG17,"V")*1)+(COUNTIF(C17:AG17,"A")*1) -> 2
B18: ='January 2026'!B18 -> Ethel Prempeh | C18: H | AC18: H | AH18: =(COUNTIF(C18:AG18,"H")*1)+(COUNTIF(C18:AG18,"H1")*0.5)+(COUNTIF(C18:AG18,"H2")*0.5)+(COUNTIF(C18:AG18,"Q")*0.25)+(COUNTIF(C18:AG18,"I")*1)+(COUNTIF(C18:AG18,"S")*0)+(COUNTIF(C18:AG18,"M")*1)+(COUNTIF(C18:AG18,"C")*0)+(COUNTIF(C18:AG18,"V")*1)+(COUNTIF(C18:AG18,"A")*1) -> 2
B19: ='January 2026'!B19 -> Isaac Appiah | C19: H | F19: S | G19: S | H19: S | I19: S | J19: S | AC19: H | AH19: =(COUNTIF(C19:AG19,"H")*1)+(COUNTIF(C19:AG19,"H1")*0.5)+(COUNTIF(C19:AG19,"H2")*0.5)+(COUNTIF(C19:AG19,"Q")*0.25)+(COUNTIF(C19:AG19,"I")*1)+(COUNTIF(C19:AG19,"S")*0)+(COUNTIF(C19:AG19,"M")*1)+(COUNTIF(C19:AG19,"C")*0)+(COUNTIF(C19:AG19,"V")*1)+(COUNTIF(C19:AG19,"A")*1) -> 2
B20: Gerald Agyapong | C20: H | AC20: H | AH20: =(COUNTIF(C20:AG20,"H")*1)+(COUNTIF(C20:AG20,"H1")*0.5)+(COUNTIF(C20:AG20,"H2")*0.5)+(COUNTIF(C20:AG20,"Q")*0.25)+(COUNTIF(C20:AG20,"I")*1)+(COUNTIF(C20:AG20,"S")*0)+(COUNTIF(C20:AG20,"M")*1)+(COUNTIF(C20:AG20,"C")*0)+(COUNTIF(C20:AG20,"V")*1)+(COUNTIF(C20:AG20,"A")*1) -> 2
B21: ='January 2026'!B21 -> 0 | J21: M | T21: S | U21: S | V21: S | W21: S | X21: S | AA21: M | AH21: =(COUNTIF(C21:AG21,"H")*1)+(COUNTIF(C21:AG21,"H1")*0.5)+(COUNTIF(C21:AG21,"H2")*0.5)+(COUNTIF(C21:AG21,"Q")*0.25)+(COUNTIF(C21:AG21,"I")*1)+(COUNTIF(C21:AG21,"S")*0)+(COUNTIF(C21:AG21,"M")*1)+(COUNTIF(C21:AG21,"C")*0)+(COUNTIF(C21:AG21,"V")*1)+(COUNTIF(C21:AG21,"A")*1) -> 1
B22: ='January 2026'!B22 -> 0 | AH22: =(COUNTIF(C22:AG22,"H")*1)+(COUNTIF(C22:AG22,"H1")*0.5)+(COUNTIF(C22:AG22,"H2")*0.5)+(COUNTIF(C22:AG22,"Q")*0.25)+(COUNTIF(C22:AG22,"I")*1)+(COUNTIF(C22:AG22,"S")*0)+(COUNTIF(C22:AG22,"M")*1)+(COUNTIF(C22:AG22,"C")*0)+(COUNTIF(C22:AG22,"V")*1)+(COUNTIF(C22:AG22,"A")*1) -> 0
B23: ='January 2026'!B23 -> 0 | AH23: =(COUNTIF(C23:AG23,"H")*1)+(COUNTIF(C23:AG23,"H1")*0.5)+(COUNTIF(C23:AG23,"H2")*0.5)+(COUNTIF(C23:AG23,"Q")*0.25)+(COUNTIF(C23:AG23,"I")*1)+(COUNTIF(C23:AG23,"S")*0)+(COUNTIF(C23:AG23,"M")*1)+(COUNTIF(C23:AG23,"C")*0)+(COUNTIF(C23:AG23,"V")*1)+(COUNTIF(C23:AG23,"A")*1) -> 0
B24: ='January 2026'!B24 -> 0 | AH24: =(COUNTIF(C24:AG24,"H")*1)+(COUNTIF(C24:AG24,"H1")*0.5)+(COUNTIF(C24:AG24,"H2")*0.5)+(COUNTIF(C24:AG24,"Q")*0.25)+(COUNTIF(C24:AG24,"I")*1)+(COUNTIF(C24:AG24,"S")*0)+(COUNTIF(C24:AG24,"M")*1)+(COUNTIF(C24:AG24,"C")*0)+(COUNTIF(C24:AG24,"V")*1)+(COUNTIF(C24:AG24,"A")*1) -> 0
B25: ='January 2026'!B25 -> 0 | AH25: =(COUNTIF(C25:AG25,"H")*1)+(COUNTIF(C25:AG25,"H1")*0.5)+(COUNTIF(C25:AG25,"H2")*0.5)+(COUNTIF(C25:AG25,"Q")*0.25)+(COUNTIF(C25:AG25,"I")*1)+(COUNTIF(C25:AG25,"S")*0)+(COUNTIF(C25:AG25,"M")*1)+(COUNTIF(C25:AG25,"C")*0)+(COUNTIF(C25:AG25,"V")*1)+(COUNTIF(C25:AG25,"A")*1) -> 0
B26: ='January 2026'!B26 -> 0 | AH26: =(COUNTIF(C26:AG26,"H")*1)+(COUNTIF(C26:AG26,"H1")*0.5)+(COUNTIF(C26:AG26,"H2")*0.5)+(COUNTIF(C26:AG26,"Q")*0.25)+(COUNTIF(C26:AG26,"I")*1)+(COUNTIF(C26:AG26,"S")*0)+(COUNTIF(C26:AG26,"M")*1)+(COUNTIF(C26:AG26,"C")*0)+(COUNTIF(C26:AG26,"V")*1)+(COUNTIF(C26:AG26,"A")*1) -> 0
B27: ='January 2026'!B27 -> 0 | AH27: =(COUNTIF(C27:AG27,"H")*1)+(COUNTIF(C27:AG27,"H1")*0.5)+(COUNTIF(C27:AG27,"H2")*0.5)+(COUNTIF(C27:AG27,"Q")*0.25)+(COUNTIF(C27:AG27,"I")*1)+(COUNTIF(C27:AG27,"S")*0)+(COUNTIF(C27:AG27,"M")*1)+(COUNTIF(C27:AG27,"C")*0)+(COUNTIF(C27:AG27,"V")*1)+(COUNTIF(C27:AG27,"A")*1) -> 0
B28: ='January 2026'!B28 -> 0 | AH28: =(COUNTIF(C28:AG28,"H")*1)+(COUNTIF(C28:AG28,"H1")*0.5)+(COUNTIF(C28:AG28,"H2")*0.5)+(COUNTIF(C28:AG28,"Q")*0.25)+(COUNTIF(C28:AG28,"I")*1)+(COUNTIF(C28:AG28,"S")*0)+(COUNTIF(C28:AG28,"M")*1)+(COUNTIF(C28:AG28,"C")*0)+(COUNTIF(C28:AG28,"V")*1)+(COUNTIF(C28:AG28,"A")*1) -> 0
B29: ='January 2026'!B29 -> 0 | AH29: =(COUNTIF(C29:AG29,"H")*1)+(COUNTIF(C29:AG29,"H1")*0.5)+(COUNTIF(C29:AG29,"H2")*0.5)+(COUNTIF(C29:AG29,"Q")*0.25)+(COUNTIF(C29:AG29,"I")*1)+(COUNTIF(C29:AG29,"S")*0)+(COUNTIF(C29:AG29,"M")*1)+(COUNTIF(C29:AG29,"C")*0)+(COUNTIF(C29:AG29,"V")*1)+(COUNTIF(C29:AG29,"A")*1) -> 0
B30: ='January 2026'!B30 -> 0 | AH30: =(COUNTIF(C30:AG30,"H")*1)+(COUNTIF(C30:AG30,"H1")*0.5)+(COUNTIF(C30:AG30,"H2")*0.5)+(COUNTIF(C30:AG30,"Q")*0.25)+(COUNTIF(C30:AG30,"I")*1)+(COUNTIF(C30:AG30,"S")*0)+(COUNTIF(C30:AG30,"M")*1)+(COUNTIF(C30:AG30,"C")*0)+(COUNTIF(C30:AG30,"V")*1)+(COUNTIF(C30:AG30,"A")*1) -> 0
B31: ='January 2026'!B31 -> 0 | AH31: =(COUNTIF(C31:AG31,"H")*1)+(COUNTIF(C31:AG31,"H1")*0.5)+(COUNTIF(C31:AG31,"H2")*0.5)+(COUNTIF(C31:AG31,"Q")*0.25)+(COUNTIF(C31:AG31,"I")*1)+(COUNTIF(C31:AG31,"S")*0)+(COUNTIF(C31:AG31,"M")*1)+(COUNTIF(C31:AG31,"C")*0)+(COUNTIF(C31:AG31,"V")*1)+(COUNTIF(C31:AG31,"A")*1) -> 0
B32: ='January 2026'!B32 -> 0 | AH32: =(COUNTIF(C32:AG32,"H")*1)+(COUNTIF(C32:AG32,"H1")*0.5)+(COUNTIF(C32:AG32,"H2")*0.5)+(COUNTIF(C32:AG32,"Q")*0.25)+(COUNTIF(C32:AG32,"I")*1)+(COUNTIF(C32:AG32,"S")*0)+(COUNTIF(C32:AG32,"M")*1)+(COUNTIF(C32:AG32,"C")*0)+(COUNTIF(C32:AG32,"V")*1)+(COUNTIF(C32:AG32,"A")*1) -> 0
B33: ='January 2026'!B33 -> 0 | AH33: =(COUNTIF(C33:AG33,"H")*1)+(COUNTIF(C33:AG33,"H1")*0.5)+(COUNTIF(C33:AG33,"H2")*0.5)+(COUNTIF(C33:AG33,"Q")*0.25)+(COUNTIF(C33:AG33,"I")*1)+(COUNTIF(C33:AG33,"S")*0)+(COUNTIF(C33:AG33,"M")*1)+(COUNTIF(C33:AG33,"C")*0)+(COUNTIF(C33:AG33,"V")*1)+(COUNTIF(C33:AG33,"A")*1) -> 0
... B55: ='January 2026'!B55 -> 0 | AH55: =(COUNTIF(C55:AG55,"H")*1)+(COUNTIF(C55:AG55,"H1")*0.5)+(COUNTIF(C55:AG55,"H2")*0.5)+(COUNTIF(C55:AG55,"Q")*0.25)+(COUNTIF(C55:AG55,"I")*1)+(COUNTIF(C55:AG55,"S")*0)+(COUNTIF(C55:AG55,"M")*1)+(COUNTIF(C55:AG55,"C")*0)+(COUNTIF(C55:AG55,"V")*1)+(COUNTIF(C55:AG55,"A")*1) -> 0

Sheet June 2026
C1: 2026
C2: Week 23 | J2: Week 24 | Q2: Week 25 | X2: Week 26 | AE2: Week 27
C3: Jun | D3: Jun | E3: Jun | F3: Jun | G3: Jun | H3: Jun | I3: Jun | J3: Jun | K3: Jun | L3: Jun | M3: Jun | N3: Jun | O3: Jun | P3: Jun | Q3: Jun | R3: Jun | S3: Jun | T3: Jun | U3: Jun | V3: Jun | W3: Jun | X3: Jun | Y3: Jun | Z3: Jun | AA3: Jun | AB3: Jun | AC3: Jun | AD3: Jun | AE3: Jun | AF3: Jun | AG3: Absences this month | AI3: Absence type | AJ3: Code | AK3: Deduction
C4: 1 | D4: 2 | E4: 3 | F4: 4 | G4: 5 | H4: 6 | I4: 7 | J4: 8 | K4: 9 | L4: 10 | M4: 11 | N4: 12 | O4: 13 | P4: 14 | Q4: 15 | R4: 16 | S4: 17 | T4: 18 | U4: 19 | V4: 20 | W4: 21 | X4: 22 | Y4: 23 | Z4: 24 | AA4: 25 | AB4: 26 | AC4: 27 | AD4: 28 | AE4: 29 | AF4: 30
C5: Mon | D5: Tue | E5: Wed | F5: Thu | G5: Fri | H5: Sat | I5: Sun | J5: Mon | K5: Tue | L5: Wed | M5: Thu | N5: Fri | O5: Sat | P5: Sun | Q5: Mon | R5: Tue | S5: Wed | T5: Thu | U5: Fri | V5: Sat | W5: Sun | X5: Mon | Y5: Tue | Z5: Wed | AA5: Thu | AB5: Fri | AC5: Sat | AD5: Sun | AE5: Mon | AF5: Tue
B6: ='January 2026'!B6 -> Patience Tsikudo | AG6: =(COUNTIF(C6:AF6,"H")*1)+(COUNTIF(C6:AF6,"H1")*0.5)+(COUNTIF(C6:AF6,"H2")*0.5)+(COUNTIF(C6:AF6,"Q")*0.25)+(COUNTIF(C6:AF6,"I")*1)+(COUNTIF(C6:AF6,"S")*0)+(COUNTIF(C6:AF6,"M")*1)+(COUNTIF(C6:AF6,"C")*0)+(COUNTIF(C6:AF6,"V")*1)+(COUNTIF(C6:AF6,"A")*1) -> 0 | AI6: Holiday | AJ6: H | AK6: 1
B7: ='January 2026'!B7 -> Emmanuel Tetteh | AG7: =(COUNTIF(C7:AF7,"H")*1)+(COUNTIF(C7:AF7,"H1")*0.5)+(COUNTIF(C7:AF7,"H2")*0.5)+(COUNTIF(C7:AF7,"Q")*0.25)+(COUNTIF(C7:AF7,"I")*1)+(COUNTIF(C7:AF7,"S")*0)+(COUNTIF(C7:AF7,"M")*1)+(COUNTIF(C7:AF7,"C")*0)+(COUNTIF(C7:AF7,"V")*1)+(COUNTIF(C7:AF7,"A")*1) -> 0 | AI7: Half Day (morning) | AJ7: H1 | AK7: 0.5
B8: ='January 2026'!B8 -> Solomon Sefah | C8: C | D8: C | E8: C | F8: C | G8: C | AG8: =(COUNTIF(C8:AF8,"H")*1)+(COUNTIF(C8:AF8,"H1")*0.5)+(COUNTIF(C8:AF8,"H2")*0.5)+(COUNTIF(C8:AF8,"Q")*0.25)+(COUNTIF(C8:AF8,"I")*1)+(COUNTIF(C8:AF8,"S")*0)+(COUNTIF(C8:AF8,"M")*1)+(COUNTIF(C8:AF8,"C")*0)+(COUNTIF(C8:AF8,"V")*1)+(COUNTIF(C8:AF8,"A")*1) -> 0 | AI8: Half Day (afternoon) | AJ8: H2 | AK8: 0.5
B9: ='January 2026'!B9 -> Maame Lankar De Veer | AG9: =(COUNTIF(C9:AF9,"H")*1)+(COUNTIF(C9:AF9,"H1")*0.5)+(COUNTIF(C9:AF9,"H2")*0.5)+(COUNTIF(C9:AF9,"Q")*0.25)+(COUNTIF(C9:AF9,"I")*1)+(COUNTIF(C9:AF9,"S")*0)+(COUNTIF(C9:AF9,"M")*1)+(COUNTIF(C9:AF9,"C")*0)+(COUNTIF(C9:AF9,"V")*1)+(COUNTIF(C9:AF9,"A")*1) -> 0 | AI9: Quarter day | AJ9: Q | AK9: 0.25
B10: ='January 2026'!B10 -> Joel Akwesi Opoku | J10: V | K10: V | L10: V | M10: V | X10: V | Y10: V | Z10: V | AG10: =(COUNTIF(C10:AF10,"H")*1)+(COUNTIF(C10:AF10,"H1")*0.5)+(COUNTIF(C10:AF10,"H2")*0.5)+(COUNTIF(C10:AF10,"Q")*0.25)+(COUNTIF(C10:AF10,"I")*1)+(COUNTIF(C10:AF10,"S")*0)+(COUNTIF(C10:AF10,"M")*1)+(COUNTIF(C10:AF10,"C")*0)+(COUNTIF(C10:AF10,"V")*1)+(COUNTIF(C10:AF10,"A")*1) -> 7 | AI10: Inactive | AJ10: I | AK10: 1
B11: ='January 2026'!B11 -> Samuel Napaa | C11: S | D11: S | G11: S | J11: V | AG11: =(COUNTIF(C11:AF11,"H")*1)+(COUNTIF(C11:AF11,"H1")*0.5)+(COUNTIF(C11:AF11,"H2")*0.5)+(COUNTIF(C11:AF11,"Q")*0.25)+(COUNTIF(C11:AF11,"I")*1)+(COUNTIF(C11:AF11,"S")*0)+(COUNTIF(C11:AF11,"M")*1)+(COUNTIF(C11:AF11,"C")*0)+(COUNTIF(C11:AF11,"V")*1)+(COUNTIF(C11:AF11,"A")*1) -> 1 | AI11: Sickness | AJ11: S | AK11: 0
B12: ='January 2026'!B12 -> Cyril Elorm Dzamaklu | AG12: =(COUNTIF(C12:AF12,"H")*1)+(COUNTIF(C12:AF12,"H1")*0.5)+(COUNTIF(C12:AF12,"H2")*0.5)+(COUNTIF(C12:AF12,"Q")*0.25)+(COUNTIF(C12:AF12,"I")*1)+(COUNTIF(C12:AF12,"S")*0)+(COUNTIF(C12:AF12,"M")*1)+(COUNTIF(C12:AF12,"C")*0)+(COUNTIF(C12:AF12,"V")*1)+(COUNTIF(C12:AF12,"A")*1) -> 0 | AI12: Maternity/Paternity | AJ12: M | AK12: 1
B13: ='January 2026'!B13 -> Edwin Sedem Lawuiekpor | AG13: =(COUNTIF(C13:AF13,"H")*1)+(COUNTIF(C13:AF13,"H1")*0.5)+(COUNTIF(C13:AF13,"H2")*0.5)+(COUNTIF(C13:AF13,"Q")*0.25)+(COUNTIF(C13:AF13,"I")*1)+(COUNTIF(C13:AF13,"S")*0)+(COUNTIF(C13:AF13,"M")*1)+(COUNTIF(C13:AF13,"C")*0)+(COUNTIF(C13:AF13,"V")*1)+(COUNTIF(C13:AF13,"A")*1) -> 0 | AI13: Compassionate | AJ13: C | AK13: 0
B14: ='January 2026'!B14 -> Emmanuel Quansah | C14: V | E14: S | F14: S | G14: S | AG14: =(COUNTIF(C14:AF14,"H")*1)+(COUNTIF(C14:AF14,"H1")*0.5)+(COUNTIF(C14:AF14,"H2")*0.5)+(COUNTIF(C14:AF14,"Q")*0.25)+(COUNTIF(C14:AF14,"I")*1)+(COUNTIF(C14:AF14,"S")*0)+(COUNTIF(C14:AF14,"M")*1)+(COUNTIF(C14:AF14,"C")*0)+(COUNTIF(C14:AF14,"V")*1)+(COUNTIF(C14:AF14,"A")*1) -> 1 | AI14: Vacation | AJ14: V | AK14: 1
B15: ='January 2026'!B15 -> Ben Oni Dankyi Ofosu | F15: V | T15: V | U15: V | X15: V | AG15: =(COUNTIF(C15:AF15,"H")*1)+(COUNTIF(C15:AF15,"H1")*0.5)+(COUNTIF(C15:AF15,"H2")*0.5)+(COUNTIF(C15:AF15,"Q")*0.25)+(COUNTIF(C15:AF15,"I")*1)+(COUNTIF(C15:AF15,"S")*0)+(COUNTIF(C15:AF15,"M")*1)+(COUNTIF(C15:AF15,"C")*0)+(COUNTIF(C15:AF15,"V")*1)+(COUNTIF(C15:AF15,"A")*1) -> 4 | AI15: Absent/No Show | AJ15: A | AK15: 1
B16: ='January 2026'!B16 -> Wahab Amoako Domson | F16: H1 | G16: H2 | J16: H1 | AG16: =(COUNTIF(C16:AF16,"H")*1)+(COUNTIF(C16:AF16,"H1")*0.5)+(COUNTIF(C16:AF16,"H2")*0.5)+(COUNTIF(C16:AF16,"Q")*0.25)+(COUNTIF(C16:AF16,"I")*1)+(COUNTIF(C16:AF16,"S")*0)+(COUNTIF(C16:AF16,"M")*1)+(COUNTIF(C16:AF16,"C")*0)+(COUNTIF(C16:AF16,"V")*1)+(COUNTIF(C16:AF16,"A")*1) -> 1.5
B17: ='January 2026'!B17 -> Emmanuel Quarshie | C17: V | G17: V | AG17: =(COUNTIF(C17:AF17,"H")*1)+(COUNTIF(C17:AF17,"H1")*0.5)+(COUNTIF(C17:AF17,"H2")*0.5)+(COUNTIF(C17:AF17,"Q")*0.25)+(COUNTIF(C17:AF17,"I")*1)+(COUNTIF(C17:AF17,"S")*0)+(COUNTIF(C17:AF17,"M")*1)+(COUNTIF(C17:AF17,"C")*0)+(COUNTIF(C17:AF17,"V")*1)+(COUNTIF(C17:AF17,"A")*1) -> 2
B18: ='January 2026'!B18 -> Ethel Prempeh | AG18: =(COUNTIF(C18:AF18,"H")*1)+(COUNTIF(C18:AF18,"H1")*0.5)+(COUNTIF(C18:AF18,"H2")*0.5)+(COUNTIF(C18:AF18,"Q")*0.25)+(COUNTIF(C18:AF18,"I")*1)+(COUNTIF(C18:AF18,"S")*0)+(COUNTIF(C18:AF18,"M")*1)+(COUNTIF(C18:AF18,"C")*0)+(COUNTIF(C18:AF18,"V")*1)+(COUNTIF(C18:AF18,"A")*1) -> 0
B19: ='January 2026'!B19 -> Isaac Appiah | J19: Q | K19: Q | L19: Q | AG19: =(COUNTIF(C19:AF19,"H")*1)+(COUNTIF(C19:AF19,"H1")*0.5)+(COUNTIF(C19:AF19,"H2")*0.5)+(COUNTIF(C19:AF19,"Q")*0.25)+(COUNTIF(C19:AF19,"I")*1)+(COUNTIF(C19:AF19,"S")*0)+(COUNTIF(C19:AF19,"M")*1)+(COUNTIF(C19:AF19,"C")*0)+(COUNTIF(C19:AF19,"V")*1)+(COUNTIF(C19:AF19,"A")*1) -> 0.75
B20: Gerald Agyapong | M20: V | Z20: S | AA20: S | AB20: S | AG20: =(COUNTIF(C20:AF20,"H")*1)+(COUNTIF(C20:AF20,"H1")*0.5)+(COUNTIF(C20:AF20,"H2")*0.5)+(COUNTIF(C20:AF20,"Q")*0.25)+(COUNTIF(C20:AF20,"I")*1)+(COUNTIF(C20:AF20,"S")*0)+(COUNTIF(C20:AF20,"M")*1)+(COUNTIF(C20:AF20,"C")*0)+(COUNTIF(C20:AF20,"V")*1)+(COUNTIF(C20:AF20,"A")*1) -> 1
